Workbook

Sheet Dashboard
A1: AI Marketplace — Project Dashboard
A2: Live totals come from the tracker. Current phase, milestone, and sprint identify the next planned delivery outcome.
A4: → Phase Tracker | B4: → Milestones | C4: → Epics | D4: → Sprints | E4: → Stories | F4: → Releases | G4: → Risks | H4: → Decision_Log
A6: Metric | B6: Value | C6: Target | D6: Status | F6: Chart Data — Phase Progress | I6: Chart Data — Story Status
A7: Overall Progress | B7: =SUMPRODUCT('Phase Tracker'!$E$2:$E$7,'Phase Tracker'!$D$2:$D$7) -> 0.594 | C7: 1 | D7: =IF(B7=1,"✅ Completed","🔄 In Progress") -> 🔄 In Progress | F7: Phase | G7: Progress % | I7: ✅ Done | J7: 28
A8: Current Phase | B8: PH2 | F8: ='Phase Tracker'!B2 -> Platform Foundation | G8: ='Phase Tracker'!E2 -> 1 | I8: 🔄 In Progress | J8: 0
A9: Current Milestone | B9: ML9 | F9: ='Phase Tracker'!B3 -> Feature Delivery (Vertical Slices) | G9: ='Phase Tracker'!E3 -> 0.72 | I9: 🚫 Blocked | J9: 0
A10: Current Sprint | B10: SP09 | F10: ='Phase Tracker'!B4 -> Production Readiness | G10: ='Phase Tracker'!E4 -> 0 | I10: ⏳ Not Started | J10: 18
A11: Completed Phases | B11: 1 | C11: =COUNTA('Phase Tracker'!$A$2:$A$7) -> 4 | D11: =IF(B11=C11,"✅ Completed","🔄 In Progress") -> 🔄 In Progress | F11: ='Phase Tracker'!B5 -> MVP Release | G11: ='Phase Tracker'!E5 -> 0
A12: Completed Milestones | B12: 9 | C12: =COUNTA(Milestones!$B$2:$B$25) -> 24 | D12: =IF(B12=C12,"✅ Completed","🔄 In Progress") -> 🔄 In Progress | F12: ='Phase Tracker'!B6 -> 0 | G12: ='Phase Tracker'!E6 -> 0
A13: Completed Epics | B13: 16 | C13: =COUNTA(Epics!$C$2:C$100) -> 23 | D13: =IF(B13=C13,"✅ Completed","🔄 In Progress") -> 🔄 In Progress | F13: ='Phase Tracker'!B7 -> 0 | G13: ='Phase Tracker'!E7 -> 0
A14: Completed Stories | B14: 37 | C14: =B15 -> 47 | D14: =IF(B14=C14,"✅ Completed","🔄 In Progress") -> 🔄 In Progress
A15: Total Stories | B15: =COUNTA(Stories!$A$2:A$200) -> 47
A16: Current Release | B16: =Releases!$B$2&" – "&Releases!$C$2&" ("&Releases!$G$2&")" -> v1.0 – AI Marketplace MVP Release (Planned)
A17: Project Health | B17: =IF(SUM(COUNTIF('Phase Tracker'!$F$2:$F$7,"*Blocked*"),COUNTIF(Milestones!$K$2:$K$25,"*Blocked*"),COUNTIF(Epics!$K$2:K$100,"*Blocked*"),COUNTIF(Sprints!$J$2:$J$26,"*Blocked*"),COUNTIF(Stories!$M$2:M$200,"*Blocked*"))>0,"🔴 At Risk",IF(B7=1,"🟢 Complete","🟢 On Track")) -> 🟢 On Track
A18: Upcoming Sprint | B18: SP10
A19: Blocked Stories | B19: =COUNTIF(Stories!$M$2:M$200,"*Blocked*") -> 0 | C19: 0 | D19: =IF(B19=0,"✅ Good","🚫 Blocked") -> ✅ Good
A20: Open Risks | B20: =COUNTIF(Risks!$H$2:$H$200,"Open") -> 0 | C20: 0 | D20: =IF(B20=0,"✅ Good","🔴 At Risk") -> ✅ Good
A21: Overall Completion % | B21: =B7 -> 0.568 | C21: 1 | D21: =IF(B21=1,"✅ Completed","🔄 In Progress") -> 🔄 In Progress
A24: Total Project Spend (AED) | B24: =Expenses!H5 -> 134.633

Sheet Phase Tracker
A1: Phase ID | B1: Phase | C1: Description | D1: Weight | E1: Progress % | F1: Status
A2: PH1 | B2: Platform Foundation | C2: Establish the engineering platform, shared infrastructure, tooling, testing framework, and knowledge base. | D2: 0.1 | E2: =IFERROR(SUMPRODUCT((Stories!$E$2:$E$200=A2)*(Stories!$P$2:$P$200))/COUNTIF(Stories!$E$2:$E$200,A2),0) -> 1 | F2: =IF(E2=1,"✅ Completed",IF(E2>0,"🔄 In Progress","⏳ Planned")) -> ✅ Completed
A3: PH2 | B3: Feature Delivery (Vertical Slices) | C3: Deliver usable, end-to-end customer, provider, and administrator outcomes: UI, APIs, data model, security rules, and tests in each story. | D3: 0.65 | E3: =IFERROR(SUMPRODUCT((Stories!$E$2:$E$200=A3)*(Stories!$P$2:$P$200))/COUNTIF(Stories!$E$2:$E$200,A3),0) -> 0.76 | F3: =IF(E3=1,"✅ Completed",IF(E3>0,"🔄 In Progress","⏳ Planned")) -> 🔄 In Progress
A4: PH3 | B4: Production Readiness | C4: Validate performance, security, operations, quality, and release readiness for the complete product. | D4: 0.2 | E4: =IFERROR(SUMPRODUCT((Stories!$E$2:$E$200=A4)*(Stories!$P$2:$P$200))/COUNTIF(Stories!$E$2:$E$200,A4),0) -> 0 | F4: =IF(E4=1,"✅ Completed",IF(E4>0,"🔄 In Progress","⏳ Planned")) -> ⏳ Planned
A5: PH4 | B5: MVP Release | C5: Deploy and hand over the approved AI Marketplace MVP. | D5: 0.05 | E5: =IFERROR(SUMPRODUCT((Stories!$E$2:$E$200=A5)*(Stories!$P$2:$P$200))/COUNTIF(Stories!$E$2:$E$200,A5),0) -> 0 | F5: =IF(E5=1,"✅ Completed",IF(E5>0,"🔄 In Progress","⏳ Planned")) -> ⏳ Planned

Sheet Milestones
A1: Sr No | B1: ID | C1: Phase ID | D1: Milestone | E1: Description | F1: Start Date | G1: Target Date | H1: Actual Completion | I1: Owner | J1: Progress % | K1: Status | L1: Hours Spent
A2: 1 | B2: ML1 | C2: PH1 | D2: Backend Foundation | E2: Establish the production-ready engineering foundation, standards, tooling, test framework, and documentation. | J2: =IFERROR(SUMPRODUCT((Stories!$D$2:$D$200=B2)*(Stories!$P$2:$P$200))/COUNTIF(Stories!$D$2:$D$200,B2),0) -> 1 | K2: =IF(COUNTIFS(Epics!$B$2:$B$100,B2,Epics!$K$2:$K$100,"*Blocked*")>0,"🚫 Blocked",IF(J2=1,"✅ Completed",IF(J2>0,"🔄 In Progress","⏳ Planned"))) -> ✅ Completed | L2: 17
A3: 2 | B3: ML2 | C3: PH2 | D3: Secure Account Access | E3: Let a user register, sign in, remain signed in, manage sessions, and access the product according to their role. | J3: =IFERROR(SUMPRODUCT((Stories!$D$2:$D$200=B3)*(Stories!$P$2:$P$200))/COUNTIF(Stories!$D$2:$D$200,B3),0) -> 1 | K3: =IF(COUNTIFS(Epics!$B$2:$B$100,B3,Epics!$K$2:$K$100,"*Blocked*")>0,"🚫 Blocked",IF(J3=1,"✅ Completed",IF(J3>0,"🔄 In Progress","⏳ Planned"))) -> ✅ Completed | L3: 0
A4: 3 | B4: ML3 | C4: PH2 | D4: Customer Profile & Locations | E4: Let customers manage their profile, preferences, language, and service locations. | J4: =IFERROR(SUMPRODUCT((Stories!$D$2:$D$200=B4)*(Stories!$P$2:$P$200))/COUNTIF(Stories!$D$2:$D$200,B4),0) -> 1 | K4: =IF(COUNTIFS(Epics!$B$2:$B$100,B4,Epics!$K$2:$K$100,"*Blocked*")>0,"🚫 Blocked",IF(J4=1,"✅ Completed",IF(J4>0,"🔄 In Progress","⏳ Planned"))) -> ✅ Completed | L4: 0
A5: 4 | B5: ML4 | C5: PH2 | D5: Provider Storefront | E5: Let providers create and manage a Business or Freelancer storefront. | J5: =IFERROR(SUMPRODUCT((Stories!$D$2:$D$200=B5)*(Stories!$P$2:$P$200))/COUNTIF(Stories!$D$2:$D$200,B5),0) -> 1 | K5: =IF(COUNTIFS(Epics!$B$2:$B$100,B5,Epics!$K$2:$K$100,"*Blocked*")>0,"🚫 Blocked",IF(J5=1,"✅ Completed",IF(J5>0,"🔄 In Progress","⏳ Planned"))) -> ✅ Completed | L5: 0
A6: 5 | B6: ML5 | C6: PH2 | D6: Provider Verification | E6: Let providers submit documents and administrators make trustworthy listing decisions. | J6: =IFERROR(SUMPRODUCT((Stories!$D$2:$D$200=B6)*(Stories!$P$2:$P$200))/COUNTIF(Stories!$D$2:$D$200,B6),0) -> 1 | K6: =IF(COUNTIFS(Epics!$B$2:$B$100,B6,Epics!$K$2:$K$100,"*Blocked*")>0,"🚫 Blocked",IF(J6=1,"✅ Completed",IF(J6>0,"🔄 In Progress","⏳ Planned"))) -> ✅ Completed | L6: 0
A7: 6 | B7: ML6 | C7: PH2 | D7: Directory & Listing Claims | E7: Let customers browse nearby providers and business owners claim seeded listings. | J7: =IFERROR(SUMPRODUCT((Stories!$D$2:$D$200=B7)*(Stories!$P$2:$P$200))/COUNTIF(Stories!$D$2:$D$200,B7),0) -> 1 | K7: =IF(COUNTIFS(Epics!$B$2:$B$100,B7,Epics!$K$2:$K$100,"*Blocked*")>0,"🚫 Blocked",IF(J7=1,"✅ Completed",IF(J7>0,"🔄 In Progress","⏳ Planned"))) -> ✅ Completed | L7: 0
A8: 7 | B8: ML7 | C8: PH2 | D8: AI-Guided Service Intake | E8: Let customers describe a need and receive a structured request even when automation requires admin help. | J8: =IFERROR(SUMPRODUCT((Stories!$D$2:$D$200=B8)*(Stories!$P$2:$P$200))/COUNTIF(Stories!$D$2:$D$200,B8),0) -> 1 | K8: =IF(COUNTIFS(Epics!$B$2:$B$100,B8,Epics!$K$2:$K$100,"*Blocked*")>0,"🚫 Blocked",IF(J8=1,"✅ Completed",IF(J8>0,"🔄 In Progress","⏳ Planned"))) -> ✅ Completed | L8: 0
A9: 8 | B9: ML8 | C9: PH2 | D9: Matching & Direct Contact | E9: Let customers see ranked matches and contact an eligible provider directly. | J9: =IFERROR(SUMPRODUCT((Stories!$D$2:$D$200=B9)*(Stories!$P$2:$P$200))/COUNTIF(Stories!$D$2:$D$200,B9),0) -> 1 | K9: =IF(COUNTIFS(Epics!$B$2:$B$100,B9,Epics!$K$2:$K$100,"*Blocked*")>0,"🚫 Blocked",IF(J9=1,"✅ Completed",IF(J9>0,"🔄 In Progress","⏳ Planned"))) -> ✅ Completed | L9: 0
A10: 9 | B10: ML9 | C10: PH2 | D10: Outcome & Reviews | E10: Let customers report hiring outcomes and leave anchor-verified reviews. | J10: =IFERROR(SUMPRODUCT((Stories!$D$2:$D$200=B10)*(Stories!$P$2:$P$200))/COUNTIF(Stories!$D$2:$D$200,B10),0) -> 1 | K10: =IF(COUNTIFS(Epics!$B$2:$B$100,B10,Epics!$K$2:$K$100,"*Blocked*")>0,"🚫 Blocked",IF(J10=1,"✅ Completed",IF(J10>0,"🔄 In Progress","⏳ Planned"))) -> ✅ Completed | L10: 0
A11: 10 | B11: ML10 | C11: PH2 | D11: Provider Leads & Analytics | E11: Let providers see leads and understand storefront visibility. | J11: =IFERROR(SUMPRODUCT((Stories!$D$2:$D$200=B11)*(Stories!$P$2:$P$200))/COUNTIF(Stories!$D$2:$D$200,B11),0) -> 0 | K11: =IF(COUNTIFS(Epics!$B$2:$B$100,B11,Epics!$K$2:$K$100,"*Blocked*")>0,"🚫 Blocked",IF(J11=1,"✅ Completed",IF(J11>0,"🔄 In Progress","⏳ Planned"))) -> ⏳ Planned | L11: 0
A12: 11 | B12: ML11 | C12: PH2 | D12: Marketplace Operations | E12: Let administrators resolve verification, manual matching, and marketplace exceptions. | J12: =IFERROR(SUMPRODUCT((Stories!$D$2:$D$200=B12)*(Stories!$P$2:$P$200))/COUNTIF(Stories!$D$2:$D$200,B12),0) -> 0 | K12: =IF(COUNTIFS(Epics!$B$2:$B$100,B12,Epics!$K$2:$K$100,"*Blocked*")>0,"🚫 Blocked",IF(J12=1,"✅ Completed",IF(J12>0,"🔄 In Progress","⏳ Planned"))) -> ⏳ Planned | L12: 0
A13: 12 | B13: ML12 | C13: PH2 | D13: Engagement & Trust | E13: Let users receive notifications, share profiles, and optionally verify visits. | J13: =IFERROR(SUMPRODUCT((Stories!$D$2:$D$200=B13)*(Stories!$P$2:$P$200))/COUNTIF(Stories!$D$2:$D$200,B13),0) -> 0 | K13: =IF(COUNTIFS(Epics!$B$2:$B$100,B13,Epics!$K$2:$K$100,"*Blocked*")>0,"🚫 Blocked",IF(J13=1,"✅ Completed",IF(J13>0,"🔄 In Progress","⏳ Planned"))) -> ⏳ Planned | L13: 0
... A16: 15 | B16: ML15 | C16: PH4 | D16: MVP Release v1.0 | E16: Deploy the validated AI Marketplace MVP with monitoring, rollback, and operational handover. | J16: =IFERROR(SUMPRODUCT((Stories!$D$2:$D$200=B16)*(Stories!$P$2:$P$200))/COUNTIF(Stories!$D$2:$D$200,B16),0) -> 0 | K16: =IF(COUNTIFS(Epics!$B$2:$B$100,B16,Epics!$K$2:$K$100,"*Blocked*")>0,"🚫 Blocked",IF(J16=1,"✅ Completed",IF(J16>0,"🔄 In Progress","⏳ Planned"))) -> ⏳ Planned | L16: 0
B17: Project_Tracker_new.xlsx
B18: Project_Tracker_new.xlsx
B19: Project_Tracker_new.xlsx
B20: Project_Tracker_new.xlsx
B21: Project_Tracker_new.xlsx
B22: Project_Tracker_new.xlsx
B23: Project_Tracker_new.xlsx
B24: Project_Tracker_new.xlsx
B25: Project_Tracker_new.xlsx

Sheet Epics
A1: Sr No | B1: Milestone ID | C1: Epic Code | D1: Epic | E1: Description | F1: Owner | G1: Start Date | H1: Target Date | I1: Actual Completion | J1: Progress % | K1: Status
A2: 1 | B2: ML1 | C2: ML1-EP01 | D2: Backend Foundation | E2: Establish the complete backend engineering platform and shared infrastructure. | J2: =IFERROR(SUMPRODUCT((Stories!$C$2:$C$200=C2)*(Stories!$P$2:$P$200))/COUNTIF(Stories!$C$2:$C$200,C2),0) -> 1 | K2: =IF(COUNTIFS(Stories!$C$2:$C$200,C2,Stories!$M$2:$M$200,"*Blocked*")>0,"🚫 Blocked",IF(J2=1,"✅ Completed",IF(J2>0,"🔄 In Progress","⏳ Planned"))) -> ✅ Completed
A3: 2 | B3: ML2 | C3: ML2-EP01 | D3: Account Registration & Sign-In | E3: Deliver mobile OTP and Google/Apple sign-in end to end. | J3: =IFERROR(SUMPRODUCT((Stories!$C$2:$C$200=C3)*(Stories!$P$2:$P$200))/COUNTIF(Stories!$C$2:$C$200,C3),0) -> 1 | K3: =IF(COUNTIFS(Stories!$C$2:$C$200,C3,Stories!$M$2:$M$200,"*Blocked*")>0,"🚫 Blocked",IF(J3=1,"✅ Completed",IF(J3>0,"🔄 In Progress","⏳ Planned"))) -> ✅ Completed
A4: 3 | B4: ML2 | C4: ML2-EP02 | D4: Secure Sessions | E4: Deliver secure session persistence and device management. | J4: =IFERROR(SUMPRODUCT((Stories!$C$2:$C$200=C4)*(Stories!$P$2:$P$200))/COUNTIF(Stories!$C$2:$C$200,C4),0) -> 1 | K4: =IF(COUNTIFS(Stories!$C$2:$C$200,C4,Stories!$M$2:$M$200,"*Blocked*")>0,"🚫 Blocked",IF(J4=1,"✅ Completed",IF(J4>0,"🔄 In Progress","⏳ Planned"))) -> ✅ Completed
A5: 4 | B5: ML2 | C5: ML2-EP03 | D5: Authorization & Auth Safety | E5: Deliver role enforcement, audit logging, and auth abuse protections. | J5: =IFERROR(SUMPRODUCT((Stories!$C$2:$C$200=C5)*(Stories!$P$2:$P$200))/COUNTIF(Stories!$C$2:$C$200,C5),0) -> 1 | K5: =IF(COUNTIFS(Stories!$C$2:$C$200,C5,Stories!$M$2:$M$200,"*Blocked*")>0,"🚫 Blocked",IF(J5=1,"✅ Completed",IF(J5>0,"🔄 In Progress","⏳ Planned"))) -> ✅ Completed
A6: 5 | B6: ML3 | C6: ML3-EP01 | D6: Customer Profile & Locations | E6: Deliver profile, preferences, bilingual UI, and saved service locations. | J6: =IFERROR(SUMPRODUCT((Stories!$C$2:$C$200=C6)*(Stories!$P$2:$P$200))/COUNTIF(Stories!$C$2:$C$200,C6),0) -> 1 | K6: =IF(COUNTIFS(Stories!$C$2:$C$200,C6,Stories!$M$2:$M$200,"*Blocked*")>0,"🚫 Blocked",IF(J6=1,"✅ Completed",IF(J6>0,"🔄 In Progress","⏳ Planned"))) -> ✅ Completed
A7: 6 | B7: ML4 | C7: ML4-EP01 | D7: Provider Storefront | E7: Deliver provider onboarding and storefront management. | J7: =IFERROR(SUMPRODUCT((Stories!$C$2:$C$200=C7)*(Stories!$P$2:$P$200))/COUNTIF(Stories!$C$2:$C$200,C7),0) -> 1 | K7: =IF(COUNTIFS(Stories!$C$2:$C$200,C7,Stories!$M$2:$M$200,"*Blocked*")>0,"🚫 Blocked",IF(J7=1,"✅ Completed",IF(J7>0,"🔄 In Progress","⏳ Planned"))) -> ✅ Completed
A8: 7 | B8: ML5 | C8: ML5-EP01 | D8: Provider Verification | E8: Deliver provider submission and verification status. | J8: =IFERROR(SUMPRODUCT((Stories!$C$2:$C$200=C8)*(Stories!$P$2:$P$200))/COUNTIF(Stories!$C$2:$C$200,C8),0) -> 1 | K8: =IF(COUNTIFS(Stories!$C$2:$C$200,C8,Stories!$M$2:$M$200,"*Blocked*")>0,"🚫 Blocked",IF(J8=1,"✅ Completed",IF(J8>0,"🔄 In Progress","⏳ Planned"))) -> ✅ Completed
A9: 8 | B9: ML5 | C9: ML5-EP02 | D9: Verification Operations | E9: Deliver administrator verification review. | J9: =IFERROR(SUMPRODUCT((Stories!$C$2:$C$200=C9)*(Stories!$P$2:$P$200))/COUNTIF(Stories!$C$2:$C$200,C9),0) -> 1 | K9: =IF(COUNTIFS(Stories!$C$2:$C$200,C9,Stories!$M$2:$M$200,"*Blocked*")>0,"🚫 Blocked",IF(J9=1,"✅ Completed",IF(J9>0,"🔄 In Progress","⏳ Planned"))) -> ✅ Completed
A10: 9 | B10: ML6 | C10: ML6-EP01 | D10: Nearby Directory | E10: Deliver browse/search by location and category. | J10: =IFERROR(SUMPRODUCT((Stories!$C$2:$C$200=C10)*(Stories!$P$2:$P$200))/COUNTIF(Stories!$C$2:$C$200,C10),0) -> 1 | K10: =IF(COUNTIFS(Stories!$C$2:$C$200,C10,Stories!$M$2:$M$200,"*Blocked*")>0,"🚫 Blocked",IF(J10=1,"✅ Completed",IF(J10>0,"🔄 In Progress","⏳ Planned"))) -> ✅ Completed
A11: 10 | B11: ML6 | C11: ML6-EP02 | D11: Listing Claims | E11: Deliver the Google-seeded business claim flow. | J11: =IFERROR(SUMPRODUCT((Stories!$C$2:$C$200=C11)*(Stories!$P$2:$P$200))/COUNTIF(Stories!$C$2:$C$200,C11),0) -> 1 | K11: =IF(COUNTIFS(Stories!$C$2:$C$200,C11,Stories!$M$2:$M$200,"*Blocked*")>0,"🚫 Blocked",IF(J11=1,"✅ Completed",IF(J11>0,"🔄 In Progress","⏳ Planned"))) -> ✅ Completed
A12: 11 | B12: ML7 | C12: ML7-EP01 | D12: AI Conversation | E12: Deliver grounded conversational intake. | J12: =IFERROR(SUMPRODUCT((Stories!$C$2:$C$200=C12)*(Stories!$P$2:$P$200))/COUNTIF(Stories!$C$2:$C$200,C12),0) -> 1 | K12: =IF(COUNTIFS(Stories!$C$2:$C$200,C12,Stories!$M$2:$M$200,"*Blocked*")>0,"🚫 Blocked",IF(J12=1,"✅ Completed",IF(J12>0,"🔄 In Progress","⏳ Planned"))) -> ✅ Completed
A13: 12 | B13: ML7 | C13: ML7-EP02 | D13: Assisted Matching | E13: Deliver low-confidence routing and search-request creation. | J13: =IFERROR(SUMPRODUCT((Stories!$C$2:$C$200=C13)*(Stories!$P$2:$P$200))/COUNTIF(Stories!$C$2:$C$200,C13),0) -> 1 | K13: =IF(COUNTIFS(Stories!$C$2:$C$200,C13,Stories!$M$2:$M$200,"*Blocked*")>0,"🚫 Blocked",IF(J13=1,"✅ Completed",IF(J13>0,"🔄 In Progress","⏳ Planned"))) -> ✅ Completed
... A24: 23 | B24: ML7 | C24: ML7-EP03 | D24: Category Domain | E24: Build and seed the real Category taxonomy domain, unblocking AI Conversation intake design. | J24: =IFERROR(SUMPRODUCT((Stories!$C$2:$C$200=C24)*(Stories!$P$2:$P$200))/COUNTIF(Stories!$C$2:$C$200,C24),0) -> 1 | K24: =IF(COUNTIFS(Stories!$C$2:$C$200,C24,Stories!$M$2:$M$200,"*Blocked*")>0,"🚫 Blocked",IF(J24=1,"✅ Completed",IF(J24>0,"🔄 In Progress","⏳ Planned"))) -> ✅ Completed

Sheet Sprints
A1: Sprint ID | B1: Sprint | C1: Theme | D1: Goal | E1: Start Date | F1: End Date | G1: Planned Stories | H1: Completed Stories | I1: Progress % | J1: Status | K1: Milestones | L1: Phases | M1: Summary Document
A2: SP01 | B2: Sprint 1 | C2: Backend Foundation | D2: Establish the production-ready backend engineering platform and shared infrastructure. | G2: =COUNTIF(Stories!$B$2:$B$200,A2) -> 18 | H2: =SUMPRODUCT((Stories!$B$2:$B$200=A2)*(Stories!$P$2:$P$200)) -> 18 | I2: =IFERROR(H2/G2,0) -> 1 | J2: =IF(COUNTIFS(Stories!$B$2:$B$200,A2,Stories!$M$2:$M$200,"*Blocked*")>0,"🚫 Blocked",IF(I2=1,"✅ Completed",IF(I2>0,"🔄 In Progress","⏳ Planned"))) -> ✅ Completed | K2: ML1 | L2: PH1
A3: SP02 | B3: Sprint 2 | C3: Secure Account Access | D3: A user can register or sign in, stay securely signed in, and access only authorized capabilities end to end. | G3: =COUNTIF(Stories!$B$2:$B$200,A3) -> 4 | H3: =SUMPRODUCT((Stories!$B$2:$B$200=A3)*(Stories!$P$2:$P$200)) -> 4 | I3: =IFERROR(H3/G3,0) -> 1 | J3: =IF(COUNTIFS(Stories!$B$2:$B$200,A3,Stories!$M$2:$M$200,"*Blocked*")>0,"🚫 Blocked",IF(I3=1,"✅ Completed",IF(I3>0,"🔄 In Progress","⏳ Planned"))) -> ✅ Completed | K3: ML2 | L3: PH2
A4: SP03 | B4: Sprint 3 | C4: Customer Profile & Locations | D4: A signed-in customer can personalize the app and select where they need a service. | G4: =COUNTIF(Stories!$B$2:$B$200,A4) -> 2 | H4: =SUMPRODUCT((Stories!$B$2:$B$200=A4)*(Stories!$P$2:$P$200)) -> 2 | I4: =IFERROR(H4/G4,0) -> 1 | J4: =IF(COUNTIFS(Stories!$B$2:$B$200,A4,Stories!$M$2:$M$200,"*Blocked*")>0,"🚫 Blocked",IF(I4=1,"✅ Completed",IF(I4>0,"🔄 In Progress","⏳ Planned"))) -> ✅ Completed | K4: ML3 | L4: PH2
A5: SP04 | B5: Sprint 4 | C5: Provider Storefront | D5: A provider can create and manage a complete business or freelancer listing. | G5: =COUNTIF(Stories!$B$2:$B$200,A5) -> 2 | H5: =SUMPRODUCT((Stories!$B$2:$B$200=A5)*(Stories!$P$2:$P$200)) -> 2 | I5: =IFERROR(H5/G5,0) -> 1 | J5: =IF(COUNTIFS(Stories!$B$2:$B$200,A5,Stories!$M$2:$M$200,"*Blocked*")>0,"🚫 Blocked",IF(I5=1,"✅ Completed",IF(I5>0,"🔄 In Progress","⏳ Planned"))) -> ✅ Completed | K5: ML4 | L5: PH2
A6: SP05 | B6: Sprint 5 | C6: Provider Verification | D6: A provider can submit verification and an administrator can approve or reject it. | G6: =COUNTIF(Stories!$B$2:$B$200,A6) -> 2 | H6: =SUMPRODUCT((Stories!$B$2:$B$200=A6)*(Stories!$P$2:$P$200)) -> 2 | I6: =IFERROR(H6/G6,0) -> 1 | J6: =IF(COUNTIFS(Stories!$B$2:$B$200,A6,Stories!$M$2:$M$200,"*Blocked*")>0,"🚫 Blocked",IF(I6=1,"✅ Completed",IF(I6>0,"🔄 In Progress","⏳ Planned"))) -> ✅ Completed | K6: ML5 | L6: PH2
A7: SP06 | B7: Sprint 6 | C7: Directory & Listing Claims | D7: A customer can browse nearby providers and an owner can claim a seeded listing. | G7: =COUNTIF(Stories!$B$2:$B$200,A7) -> 2 | H7: =SUMPRODUCT((Stories!$B$2:$B$200=A7)*(Stories!$P$2:$P$200)) -> 2 | I7: =IFERROR(H7/G7,0) -> 1 | J7: =IF(COUNTIFS(Stories!$B$2:$B$200,A7,Stories!$M$2:$M$200,"*Blocked*")>0,"🚫 Blocked",IF(I7=1,"✅ Completed",IF(I7>0,"🔄 In Progress","⏳ Planned"))) -> ✅ Completed | K7: ML6 | L7: PH2
A8: SP07 | B8: Sprint 7 | C8: AI-Guided Service Intake | D8: A customer can describe a need and receive a structured request, including manual fallback. | G8: =COUNTIF(Stories!$B$2:$B$200,A8) -> 3 | H8: =SUMPRODUCT((Stories!$B$2:$B$200=A8)*(Stories!$P$2:$P$200)) -> 3 | I8: =IFERROR(H8/G8,0) -> 1 | J8: =IF(COUNTIFS(Stories!$B$2:$B$200,A8,Stories!$M$2:$M$200,"*Blocked*")>0,"🚫 Blocked",IF(I8=1,"✅ Completed",IF(I8>0,"🔄 In Progress","⏳ Planned"))) -> ✅ Completed | K8: ML7 | L8: PH2
A9: SP08 | B9: Sprint 8 | C9: Matching & Direct Contact | D9: A customer can view ranked matches and contact an eligible provider directly. | G9: =COUNTIF(Stories!$B$2:$B$200,A9) -> 2 | H9: =SUMPRODUCT((Stories!$B$2:$B$200=A9)*(Stories!$P$2:$P$200)) -> 2 | I9: =IFERROR(H9/G9,0) -> 1 | J9: =IF(COUNTIFS(Stories!$B$2:$B$200,A9,Stories!$M$2:$M$200,"*Blocked*")>0,"🚫 Blocked",IF(I9=1,"✅ Completed",IF(I9>0,"🔄 In Progress","⏳ Planned"))) -> ✅ Completed | K9: ML8 | L9: PH2
A10: SP09 | B10: Sprint 9 | C10: Outcome & Reviews | D10: A customer can share hiring outcomes and verified feedback. | G10: =COUNTIF(Stories!$B$2:$B$200,A10) -> 2 | H10: =SUMPRODUCT((Stories!$B$2:$B$200=A10)*(Stories!$P$2:$P$200)) -> 2 | I10: =IFERROR(H10/G10,0) -> 1 | J10: =IF(COUNTIFS(Stories!$B$2:$B$200,A10,Stories!$M$2:$M$200,"*Blocked*")>0,"🚫 Blocked",IF(I10=1,"✅ Completed",IF(I10>0,"🔄 In Progress","⏳ Planned"))) -> ✅ Completed | K10: ML9 | L10: PH2
A11: SP10 | B11: Sprint 10 | C11: Provider Leads & Analytics | D11: A provider can see leads and storefront visibility. | G11: =COUNTIF(Stories!$B$2:$B$200,A11) -> 2 | H11: =SUMPRODUCT((Stories!$B$2:$B$200=A11)*(Stories!$P$2:$P$200)) -> 0 | I11: =IFERROR(H11/G11,0) -> 0 | J11: =IF(COUNTIFS(Stories!$B$2:$B$200,A11,Stories!$M$2:$M$200,"*Blocked*")>0,"🚫 Blocked",IF(I11=1,"✅ Completed",IF(I11>0,"🔄 In Progress","⏳ Planned"))) -> ⏳ Planned | K11: ML10 | L11: PH2
A12: SP11 | B12: Sprint 11 | C12: Marketplace Operations | D12: An administrator can operate verification, matching, and exception workflows. | G12: =COUNTIF(Stories!$B$2:$B$200,A12) -> 2 | H12: =SUMPRODUCT((Stories!$B$2:$B$200=A12)*(Stories!$P$2:$P$200)) -> 0 | I12: =IFERROR(H12/G12,0) -> 0 | J12: =IF(COUNTIFS(Stories!$B$2:$B$200,A12,Stories!$M$2:$M$200,"*Blocked*")>0,"🚫 Blocked",IF(I12=1,"✅ Completed",IF(I12>0,"🔄 In Progress","⏳ Planned"))) -> ⏳ Planned | K12: ML11 | L12: PH2
A13: SP12 | B13: Sprint 12 | C13: Engagement & Trust | D13: Users can receive notifications, share profiles, and verify visits. | G13: =COUNTIF(Stories!$B$2:$B$200,A13) -> 2 | H13: =SUMPRODUCT((Stories!$B$2:$B$200=A13)*(Stories!$P$2:$P$200)) -> 0 | I13: =IFERROR(H13/G13,0) -> 0 | J13: =IF(COUNTIFS(Stories!$B$2:$B$200,A13,Stories!$M$2:$M$200,"*Blocked*")>0,"🚫 Blocked",IF(I13=1,"✅ Completed",IF(I13>0,"🔄 In Progress","⏳ Planned"))) -> ⏳ Planned | K13: ML12 | L13: PH2
... A16: SP15 | B16: Sprint 15 | C16: MVP Release | D16: The AI Marketplace MVP is deployed and operationally handed over. | G16: =COUNTIF(Stories!$B$2:$B$200,A16) -> 1 | H16: =SUMPRODUCT((Stories!$B$2:$B$200=A16)*(Stories!$P$2:$P$200)) -> 0 | I16: =IFERROR(H16/G16,0) -> 0 | J16: =IF(COUNTIFS(Stories!$B$2:$B$200,A16,Stories!$M$2:$M$200,"*Blocked*")>0,"🚫 Blocked",IF(I16=1,"✅ Completed",IF(I16>0,"🔄 In Progress","⏳ Planned"))) -> ⏳ Planned | K16: ML15 | L16: PH4

Sheet Sprint_Epics
A1: Sprint ID | B1: Epic Code | C1: Milestone ID
A2: SP01 | B2: ML1-EP01 | C2: ML1
A3: SP02 | B3: ML2-EP01 | C3: ML2
A4: SP02 | B4: ML2-EP02 | C4: ML2
A5: SP02 | B5: ML2-EP03 | C5: ML2
A6: SP03 | B6: ML3-EP01 | C6: ML3
A7: SP04 | B7: ML4-EP01 | C7: ML4
A8: SP05 | B8: ML5-EP01 | C8: ML5
A9: SP05 | B9: ML5-EP02 | C9: ML5
A10: SP06 | B10: ML6-EP01 | C10: ML6
A11: SP06 | B11: ML6-EP02 | C11: ML6
A12: SP07 | B12: ML7-EP01 | C12: ML7
... A23: SP15 | B23: ML15-EP01 | C23: ML15

Sheet Stories
A1: Story ID | B1: Sprint ID | C1: Epic Code | D1: Milestone ID | E1: Phase ID | F1: Title | G1: Description | H1: Acceptance Criteria | I1: Priority | J1: Estimate (Hours) | K1: Actual Hours | L1: Story Points | M1: Status | N1: Assignee | O1: Depends On | P1: Progress %
A2: BF-001 | B2: SP01 | C2: ML1-EP01 | D2: ML1 | E2: PH1 | F2: FastAPI Project Structure | G2: As a developer, I want a standardized FastAPI project structure so the codebase is modular and scalable. Acceptance criteria: approved folder structure; application starts successfully. | I2: High | K2: 17 | M2: ✅ Done | P2: =IF(ISNUMBER(SEARCH("Done",M2)),1,IF(ISNUMBER(SEARCH("In Progress",M2)),0.5,0)) -> 1
A3: BF-002 | B3: SP01 | C3: ML1-EP01 | D3: ML1 | E3: PH1 | F3: Centralized Configuration | G3: As a developer, I want configuration centralized, validated, and loaded from environment variables so the application is secure and environment independent. Acceptance criteria: Pydantic Settings loads .env; no hardcoded configuration. | I3: High | M3: ✅ Done | O3: BF-001 | P3: =IF(ISNUMBER(SEARCH("Done",M3)),1,IF(ISNUMBER(SEARCH("In Progress",M3)),0.5,0)) -> 1
A4: BF-003 | B4: SP01 | C4: ML1-EP01 | D4: ML1 | E4: PH1 | F4: Database Connectivity | G4: As a developer, I want async SQLAlchemy and PostgreSQL connectivity so the application persists data reliably. Acceptance criteria: application connects successfully to PostgreSQL. | I4: High | M4: ✅ Done | O4: BF-002 | P4: =IF(ISNUMBER(SEARCH("Done",M4)),1,IF(ISNUMBER(SEARCH("In Progress",M4)),0.5,0)) -> 1
A5: BF-004 | B5: SP01 | C5: ML1-EP01 | D5: ML1 | E5: PH1 | F5: Alembic Migrations | G5: As a developer, I want version-controlled database migrations. Acceptance criteria: an initial migration can be created and applied. | I5: High | M5: ✅ Done | O5: BF-003 | P5: =IF(ISNUMBER(SEARCH("Done",M5)),1,IF(ISNUMBER(SEARCH("In Progress",M5)),0.5,0)) -> 1
A6: BF-005 | B6: SP01 | C6: ML1-EP01 | D6: ML1 | E6: PH1 | F6: Application Lifecycle Management | G6: As a developer, I want application startup and shutdown managed safely. Acceptance criteria: lifespan events initialize and release resources without errors. | I6: High | M6: ✅ Done | O6: BF-003 | P6: =IF(ISNUMBER(SEARCH("Done",M6)),1,IF(ISNUMBER(SEARCH("In Progress",M6)),0.5,0)) -> 1
A7: BF-006 | B7: SP01 | C7: ML1-EP01 | D7: ML1 | E7: PH1 | F7: API Versioning | G7: As a developer, I want API versioning so future API changes remain compatible. Acceptance criteria: endpoints are available under /api/v1. | I7: High | M7: ✅ Done | O7: BF-001 | P7: =IF(ISNUMBER(SEARCH("Done",M7)),1,IF(ISNUMBER(SEARCH("In Progress",M7)),0.5,0)) -> 1
A8: BF-007 | B8: SP01 | C8: ML1-EP01 | D8: ML1 | E8: PH1 | F8: Health Check Endpoints | G8: As a developer, I want health checks so I can verify application and database availability. Acceptance criteria: application and database health endpoints respond correctly. | I8: High | M8: ✅ Done | O8: BF-003 | P8: =IF(ISNUMBER(SEARCH("Done",M8)),1,IF(ISNUMBER(SEARCH("In Progress",M8)),0.5,0)) -> 1
A9: BF-008 | B9: SP01 | C9: ML1-EP01 | D9: ML1 | E9: PH1 | F9: Structured Logging | G9: As a developer, I want structured logging so application behavior is easy to monitor and troubleshoot. Acceptance criteria: requests, errors, and startup events are logged consistently. | I9: Medium | M9: ✅ Done | O9: BF-002 | P9: =IF(ISNUMBER(SEARCH("Done",M9)),1,IF(ISNUMBER(SEARCH("In Progress",M9)),0.5,0)) -> 1
A10: BF-009 | B10: SP01 | C10: ML1-EP01 | D10: ML1 | E10: PH1 | F10: Global Exception Handling | G10: As a developer, I want consistent API errors. Acceptance criteria: validation, business, and unexpected exceptions return standardized responses. | I10: High | M10: ✅ Done | O10: BF-001 | P10: =IF(ISNUMBER(SEARCH("Done",M10)),1,IF(ISNUMBER(SEARCH("In Progress",M10)),0.5,0)) -> 1
A11: BF-010 | B11: SP01 | C11: ML1-EP01 | D11: ML1 | E11: PH1 | F11: Standardized API Response Models | G11: As a developer, I want reusable response models so every endpoint returns a consistent contract. Acceptance criteria: success, paginated, and error schemas are reusable and tested. | I11: High | M11: ✅ Done | O11: BF-009 | P11: =IF(ISNUMBER(SEARCH("Done",M11)),1,IF(ISNUMBER(SEARCH("In Progress",M11)),0.5,0)) -> 1
A12: BF-011 | B12: SP01 | C12: ML1-EP01 | D12: ML1 | E12: PH1 | F12: Security Utilities | G12: As a developer, I want password hashing, JWT helpers, and security dependencies prepared for authentication. Acceptance criteria: utilities are available without introducing business features. | I12: Medium | M12: ✅ Done | O12: BF-002 | P12: =IF(ISNUMBER(SEARCH("Done",M12)),1,IF(ISNUMBER(SEARCH("In Progress",M12)),0.5,0)) -> 1
A13: BF-012 | B13: SP01 | C13: ML1-EP01 | D13: ML1 | E13: PH1 | F13: Repository Layer | G13: As a developer, I want data access isolated from business logic. Acceptance criteria: base repository and repository interfaces are implemented. | I13: Medium | M13: ✅ Done | O13: BF-003 | P13: =IF(ISNUMBER(SEARCH("Done",M13)),1,IF(ISNUMBER(SEARCH("In Progress",M13)),0.5,0)) -> 1
A14: BF-013 | B14: SP01 | C14: ML1-EP01 | D14: ML1 | E14: PH1 | F14: Service Layer & Repository Contracts | G14: As a developer, I want services separated from routers and repositories. Acceptance criteria: Router → Service → Repository → Database pattern is enforced. | I14: Medium | M14: ✅ Done | O14: BF-012 | P14: =IF(ISNUMBER(SEARCH("Done",M14)),1,IF(ISNUMBER(SEARCH("In Progress",M14)),0.5,0)) -> 1
... A19: BF-018 | B19: SP01 | C19: ML1-EP01 | D19: ML1 | E19: PH1 | F19: Project Documentation | G19: As a contributor, I want current project documentation so implementation follows approved product and engineering decisions. Acceptance criteria: the centralized project knowledge base is available. | I19: Medium | M19: ✅ Done | O19: BF-001 | P19: =IF(ISNUMBER(SEARCH("Done",M19)),1,IF(ISNUMBER(SEARCH("In Progress",M19)),0.5,0)) -> 1
A20: AUTH-001 | B20: SP02 | C20: ML2-EP01 | D20: ML2 | E20: PH2 | F20: Register and sign in with Mobile OTP | G20: As a new or returning user, I want to register or sign in with my mobile number and a one-time password, so that I can securely access the app without managing a password. This story covers the mobile OTP path of registration and login only (Google/Apple OAuth is AUTH-002). It establishes the Identity domain's foundational data model (users, roles, permissions, devices) and the OTP mechanism reused later by arrival-verification and claim-listing flows. A new phone number creates a User and assigns the customer role by default; no Customer Profile row is created here -- that is explicitly deferred to the Customer domain (CUS-001), since registration only produces an authenticated Account, not a profile. Scope boundary: does not include Google/Apple sign-in, session/refresh-token management (AUTH-003), or role-based authorization enforcement (AUTH-004). | H20: 1. users, roles, permissions, role_permissions, user_roles, devices, and otp_verifications tables exist via Alembic migration, with partial unique constraints on email, phone number, and external_auth_subject. 2. customer, provider, and admin roles are seeded and idempotent to re-run. 3. POST request-otp accepts a phone number and country code, generates a 6-digit code, stores only its hash, and sets a 5-minute expiry. 4. OTP delivery is stubbed behind an SmsSender interface; no real provider is called in this story. 5. POST verify-otp rejects an incorrect code without revealing whether the phone number is registered, and increments an attempt counter capped at 5 attempts before lockout. 6. A verified OTP for an unrecognized phone number creates a new User with auth_provider=mobile_otp and assigns the customer role via user_roles. 7. A verified OTP for an existing phone number authenticates that User without creating a duplicate. 8. A used OTP code cannot be verified a second time (verified_at is set and checked). 9. Mobile screens implement splash, language selection, phone entry, and OTP entry with a visible resend countdown matching the 5-minute expiry. 10. Error states use plain-language copy (e.g., "That code didn't work -- check the digits and try again") with no internal error codes or stack traces shown. 11. Automated tests cover: new-number registration, existing-number login, expired code rejection, attempt-cap lockout, and reused-code rejection. 12. No customer_profiles or customer_preferences row is created as a result of this story. | I20: Critical | M20: ✅ Done | O20: BF-018 | P20: =IF(ISNUMBER(SEARCH("Done",M20)),1,IF(ISNUMBER(SEARCH("In Progress",M20)),0.5,0)) -> 1
A21: AUTH-002 | B21: SP02 | C21: ML2-EP01 | D21: ML2 | E21: PH2 | F21: Register and sign in with Google or Apple | G21: As a new or returning user, I want to continue with Google or Apple, so that I can access the app using an identity I already trust, without creating a new credential. This story adds the OAuth path alongside AUTH-001's mobile OTP path -- both lead to the same underlying User record shape. Server-side ID-token verification is mandatory; the client's assertion of identity is never trusted directly. Accounts are matched on the (auth_provider, external_auth_subject) pair, not on email, because social email addresses can be unverified or change. Scope boundary: does not include account linking/merging across providers -- a different provider with the same email produces a second, separate Account by design in this story, and any future account-linking capability is out of scope here. | H21: 1. Sign-in screen offers Google and Apple buttons alongside the mobile-number option from AUTH-001. 2. Backend verifies the Google ID token against Google's public keys and the Apple identity token against Apple's public keys -- no token is trusted without verification. 3. A new (auth_provider, external_auth_subject) pair creates a new User and assigns the customer role. 4. An existing (auth_provider, external_auth_subject) pair authenticates the existing User. 5. A different provider presenting the same email as an existing account creates a second, independent Account -- it does not merge or link to the first. 6. Invalid, expired, or tampered ID tokens are rejected with a generic authentication-failure message, not a detailed validation error. 7. User cancellation mid-flow (e.g., closing the Google/Apple consent screen) returns the user to the sign-in screen without a crash or a stuck loading state. 8. Automated tests use signed test tokens or mocked provider key endpoints -- no test calls the real Google or Apple endpoints. 9. Integration test explicitly verifies the different-provider-same-email case results in two distinct User rows. | I21: High | M21: ✅ Done | O21: AUTH-001 | P21: =IF(ISNUMBER(SEARCH("Done",M21)),1,IF(ISNUMBER(SEARCH("In Progress",M21)),0.5,0)) -> 1
A22: AUTH-003 | B22: SP02 | C22: ML2-EP02 | D22: ML2 | E22: PH2 | F22: Stay signed in and manage active sessions | G22: As an authenticated user, I want to remain signed in securely across app restarts and see/manage my active sessions, so that I stay logged in conveniently while retaining control if a device is lost or compromised. This story implements JWT access-token issuance, refresh-token rotation, and per-device session tracking, building on the User records created in AUTH-001/AUTH-002. Access tokens are short-lived and carry no PII; refresh tokens are opaque and stored only as a hash. A device is recorded per login so a user can distinguish and revoke sessions individually. Scope boundary: does not include role-based authorization (AUTH-004) -- this story only establishes that a session exists and can be trusted, not what it's allowed to do. | H22: 1. sessions, refresh_tokens, and devices tables exist via migration, linked to users. 2. Successful login (via either AUTH-001 or AUTH-002) issues a 15-minute JWT access token containing only sub, exp, iat, jti, and roles -- no email or phone number in the payload. 3. A refresh token is an opaque random string; only its hash is persisted, never the raw value. 4. Calling the refresh endpoint with a valid, unexpired refresh token issues a new access/refresh pair and invalidates the previous refresh token (rotation). 5. Calling the refresh endpoint with an already-used (rotated-away) or revoked refresh token is rejected. 6. A device row is created or updated on login capturing platform (iOS/Android) and a device name. 7. GET sessions lists the caller's active sessions with device name, platform, and last-seen time, flagging the current session. 8. DELETE on a single session revokes that session's refresh tokens; a subsequent refresh attempt with that session's token fails. 9. A "log out everywhere" action revokes every session except optionally the current one, and is a distinct, separately-labeled action from single-session revocation. 10. A user cannot list or revoke another user's sessions (ownership enforced, tested explicitly). 11. Automated tests cover rotation, revocation-then-refresh-fails, and the ownership boundary. | I22: High | M22: ✅ Done | O22: AUTH-001, AUTH-002 | P22: =IF(ISNUMBER(SEARCH("Done",M22)),1,IF(ISNUMBER(SEARCH("In Progress",M22)),0.5,0)) -> 1
A23: AUTH-004 | B23: SP02 | C23: ML2-EP03 | D23: ML2 | E23: PH2 | F23: Access the app according to my role | G23: As a customer, provider, or administrator, I want the app and API to enforce what I'm allowed to do based on my role, so that my account and the platform's other users are protected from unauthorized actions. This story adds the reusable authorization layer every later feature story depends on: a role-check dependency, correct 401-vs-403 semantics, and an audit trail for security-sensitive identity events. It also adds rate limiting to the authentication endpoints built in AUTH-001-003, since an unprotected auth surface is the highest-value target for abuse. This is the last story in the Secure Account Access sprint and is a hard dependency for every subsequent feature sprint's protected endpoints. Scope boundary: this story proves the mechanism end-to-end against one representative endpoint (GET /auth/me); it does not retroactively add authorization checks to endpoints that don't exist yet -- those checks are each later story's own responsibility to add. | H23: 1. A require_role() dependency exists and can be applied to any endpoint, checking the roles claim from the validated JWT. 2. A request with no token, an invalid token, or an expired token receives 401 Unauthorized. 3. A request with a valid token but a disallowed role receives 403 Forbidden -- 401 and 403 are never used interchangeably. 4. An ownership-check helper exists returning 404 (not 403) when revealing a resource's existence would itself be a leak. 5. GET /auth/me returns the caller's own id, roles, and account status, and is protected by require_role(). 6. Auth endpoints (OTP request/verify, OAuth login, refresh) are rate-limited via Redis at 10 requests/minute per the security standard, keyed appropriately (phone number, IP, or user id). 7. Rate-limit rejections return a generic "too many attempts, try again later" message that never confirms or denies whether an account exists. 8. audit_logs table exists (immutable -- no soft-delete or version columns) and receives a record for registration, login, logout, and session revocation events, with no secrets or tokens in before/after_state. 9. Automated tests cover: 401 vs 403 distinction, rate-limit triggering and reset, and an audit-log row being created for each of the four tracked event types. | I23: High | M23: ✅ Done | O23: AUTH-003 | P23: =IF(ISNUMBER(SEARCH("Done",M23)),1,IF(ISNUMBER(SEARCH("In Progress",M23)),0.5,0)) -> 1
A24: CUS-001 | B24: SP03 | C24: ML3-EP01 | D24: ML3 | E24: PH2 | F24: Set up my customer profile and preferences | G24: As a newly registered user, I want a customer profile created automatically with sensible defaults, and the ability to update my display name, avatar, language, and notification channel, so that the app is personalized to me without extra signup steps. This story wires the Customer domain's auto-provisioning trigger into the registration flows completed in AUTH-001/AUTH-002 -- every new Account now also gets a customer_profiles and customer_preferences row in the same transaction. It is deliberately the first story of the Customer Profile & Locations sprint because every later Customer-facing feature (saved addresses, search, activity) assumes a Customer Profile already exists. Scope boundary: does not include saved addresses (CUS-002) or the Provider-side profile equivalent (PRO-001/002). | H24: 1. customer_profiles and customer_preferences tables exist via migration, one-to-one with users. 2. Completing registration via AUTH-001 or AUTH-002 creates a customer_profiles row and a customer_preferences row in the same database transaction as the User creation -- never as a separate, possibly-failing follow-up call. 3. Default notification channel is WhatsApp; default language is derived from device locale, falling back to English. 4. GET/PATCH endpoints allow reading and updating display name, avatar, language, and notification channel/category preferences. 5. Profile & Settings screen displays and allows editing these fields, plus a visible language toggle. 6. Changing language updates customer_preferences.language and is reflected immediately in the UI without requiring app restart. 7. A user cannot read or update another user's customer profile (ownership enforced). 8. Automated tests confirm profile auto-creation happens atomically with registration. 9. RTL layout verified for the Profile & Settings screen in Arabic. | I24: High | M24: ✅ Done | O24: AUTH-004 | P24: =IF(ISNUMBER(SEARCH("Done",M24)),1,IF(ISNUMBER(SEARCH("In Progress",M24)),0.5,0)) -> 1
A25: CUS-002 | B25: SP03 | C25: ML3-EP01 | D25: ML3 | E25: PH2 | F25: Manage my service locations | G25: As a customer, I want to save, edit, and remove addresses, and optionally add one during onboarding, so that I don't have to re-enter my location every time I search for a service. This story implements Saved Addresses, the location data every future Search Request depends on. Adding a first address is explicitly skippable at registration per the product's friction-reduction principle -- the app must re-prompt only when an address is actually needed (submitting a search), not before. Scope boundary: does not include the geospatial proximity-matching infrastructure itself (a later Provider/Matching-domain story) -- this story only captures and manages address data. | H25: 1. saved_addresses table exists via migration, linked to customer_profiles, with a label, address line, city, region, country code, latitude/longitude, and a default flag. 2. Exactly one address per customer can be marked default at a time (setting a new default un-sets the previous one). 3. Add-address screen supports both map-pin selection and manual entry, plus a "use current location" option. 4. The first-address prompt at registration is skippable; skipping does not block registration completion or any other onboarding step. 5. If skipped, the app does not re-prompt for an address until the customer actually attempts to submit a search request. 6. Saved Addresses management screen lists all addresses with the default clearly indicated, and supports edit and delete. 7. Deleting the currently-default address either prompts the customer to choose a new default or clearly indicates no default is set. 8. A customer cannot view or modify another customer's addresses (ownership enforced). 9. Automated tests cover: default-address uniqueness, skip-then-required-later flow, and the ownership boundary. | I25: High | M25: ✅ Done | O25: CUS-001 | P25: =IF(ISNUMBER(SEARCH("Done",M25)),1,IF(ISNUMBER(SEARCH("In Progress",M25)),0.5,0)) -> 1
A26: PRO-001 | B26: SP04 | C26: ML4-EP01 | D26: ML4 | E26: PH2 | F26: Create my business or freelancer listing | G26: As a user who wants to offer a service, I want to choose whether I'm a Business or a Freelancer and enter my core details, so that I can list my business or service on the platform for free. This story adds the Provider domain's core aggregate and the first half of the onboarding flow: type selection (immutable afterward -- a Provider is exactly one subtype, never both) and subtype-specific details (fixed location/hours for a Business, base location/travel radius for a Freelancer). Critically, this reuses the caller's existing Account from AUTH-001/002 rather than creating a new one -- a Customer choosing to also list a business does not register again, consistent with the platform's dual-role model. Scope boundary: does not include portfolio/availability management (PRO-002) or the Verification gate (VER-001) -- a newly created Provider is not yet discoverable to customers. | H26: 1. providers, business_profiles, and freelancer_profiles tables exist via migration; providers.user_id is nullable (to support Google-seeded unclaimed listings in a later story) but non-null for self-registered providers created here. 2. A user with an existing Account can start "List Your Business" and the resulting Provider is linked to that same Account -- no new registration/OTP/OAuth step is triggered. 3. Provider type (Business or Freelancer) is selected via a dedicated screen and cannot be changed after this step completes. 4. Basic info (display name, phone, WhatsApp, category, description) is captured before type-specific details. 5. Business path captures address/map location, weekly operating hours, optional delivery radius, and optional trade license number. 6. Freelancer path captures base location, service radius, skill tags, and years of experience. 7. A newly created Provider defaults to verification_status=pending and is_discoverable=false -- it must not appear in any customer-facing search or directory result. 8. A user cannot create a second Provider on the same Account (one Provider per Account, enforced at the service layer, tested explicitly). 9. Step indicator is visible across the multi-step form; each step is independently completable in under 30 seconds per the UX guideline. 10. Automated tests cover: type immutability, one-provider-per-account enforcement, and correct defaulting of verification/discoverability flags. | I26: Critical | M26: ✅ Done | O26: AUTH-004, CUS-002 | P26: =IF(ISNUMBER(SEARCH("Done",M26)),1,IF(ISNUMBER(SEARCH("In Progress",M26)),0.5,0)) -> 1
A27: PRO-002 | B27: SP04 | C27: ML4-EP01 | D27: ML4 | E27: PH2 | F27: Manage my provider storefront | G27: As a provider, I want to upload portfolio photos, set my weekly availability, and edit my listing after onboarding, so that my storefront stays current and represents my work well. This story completes the provider aggregate (portfolios, provider_availability, provider_categories, service_areas) and delivers the ongoing Storefront screen, distinct from the one-time onboarding flow in PRO-001. It frames the provider profile as the provider's free digital storefront, per the product's positioning. Scope boundary: does not include visibility analytics (LEAD-002) or leads (LEAD-001) -- this story is limited to editing the storefront's own content. | H27: 1. portfolios, provider_availability, provider_categories, and service_areas tables exist via migration. 2. Provider can add, remove, and reorder portfolio photos; each upload is validated for MIME type, extension, and size, and stored under a generated (never user-supplied) filename. 3. Provider can set open/closed status and hours per weekday, plus a separate emergency/urgent-availability flag. 4. Provider can belong to one or more categories via provider_categories, with exactly one marked primary. 5. Storefront screen shows editable sections for basic info, subtype-specific details, portfolio, and availability, each independently saveable. 6. Edits to basic info, hours, or portfolio do not require re-submitting verification unless the change affects a verified field -- that boundary is explicitly documented in this story's implementation notes. 7. A provider cannot edit another provider's storefront (ownership enforced). 8. Automated tests cover portfolio reordering persistence, availability CRUD, and the ownership boundary. | I27: High | M27: ✅ Done | O27: PRO-001 | P27: =IF(ISNUMBER(SEARCH("Done",M27)),1,IF(ISNUMBER(SEARCH("In Progress",M27)),0.5,0)) -> 1
A28: VER-001 | B28: SP05 | C28: ML5-EP01 | D28: ML5 | E28: PH2 | F28: Submit my provider verification | G28: As a provider, I want to upload the right identity or license document and see what the system read from it before submitting, so that I can go live on the platform with confidence my submission is correct. This story implements the Verification domain's document-upload half: verification_records/verification_documents, an OCR-assisted confirmation step, and the mandatory-for-Freelancer / configurable-for-Business trust gate. The OCR integration itself is stubbed pending confirmation of the existing Ejari/Emirates ID pipeline's interface -- this story does not build a new OCR engine from scratch. Scope boundary: does not include the admin review/approval side (VER-002) -- this story only gets a submission into the pending queue correctly. | H28: 1. verification_records and verification_documents tables exist via migration, with a status enum (pending, under_review, approved, rejected). 2. Freelancer providers must submit an Emirates-ID-equivalent document; Business providers submit per the configured (lighter) verification bar. 3. Upload validates MIME type, extension, and file size before accepting; rejected uploads show a specific, actionable error. 4. After upload, a confirmation screen shows OCR-extracted fields (name, ID number, expiry date where applicable) as editable, with copy explicitly framing them as "what we read -- please confirm," not as already-verified fact. 5. Submitting creates a verification_records row with status=pending; the provider's discoverability is unaffected until VER-002 processes it. 6. A provider can view their own current verification status but cannot self-approve. 7. Resubmission after a rejection creates a new verification cycle rather than mutating the rejected record, preserving history. 8. Automated tests cover: upload validation rejections, the OCR-confirmation-is-editable requirement, and that submission alone never changes is_discoverable. | I28: Critical | M28: ✅ Done | O28: PRO-001 | P28: =IF(ISNUMBER(SEARCH("Done",M28)),1,IF(ISNUMBER(SEARCH("In Progress",M28)),0.5,0)) -> 1
A29: VER-002 | B29: SP05 | C29: ML5-EP02 | D29: ML5 | E29: PH2 | F29: Review provider verification as an administrator | G29: As an administrator, I want to review a provider's submitted documents and approve or reject with a reason, so that only genuinely verified providers become discoverable -- a safety requirement, not just a quality one, since Freelancers enter customers' homes. This story completes the Verification domain's trust-gate enforcement: approving or rejecting must atomically update the provider's cached discoverability flag in the same transaction as the status change, and the provider must be notified either way. Scope boundary: does not include the broader admin operations dashboard (ADM-002) -- this story is limited to the verification-review action itself and its direct consequences. | H29: 1. Admin-only endpoint lists pending/under_review verification_records with linked documents. 2. Approving a record sets status=approved, records reviewed_by and reviewed_at, and in the same transaction sets providers.verification_status=approved and, for Freelancers, is_discoverable=true. 3. Rejecting a record requires a rejection_reason, sets status=rejected, and does not set is_discoverable=true under any circumstance. 4. A Freelancer's is_discoverable can never be true while the latest verification_records status is anything other than approved -- this invariant is asserted directly in an automated test. 5. The provider receives a notification on status change, worded in plain language, never exposing internal status enum values. 6. Every approval/rejection action is written to admin_action_log. 7. A non-admin cannot access the review endpoint (403). 8. Automated tests cover the atomic status+discoverability update and the notification trigger. | I29: High | M29: ✅ Done | O29: VER-001 | P29: =IF(ISNUMBER(SEARCH("Done",M29)),1,IF(ISNUMBER(SEARCH("In Progress",M29)),0.5,0)) -> 1
A30: DIR-001 | B30: SP06 | C30: ML6-EP01 | D30: ML6 | E30: PH2 | F30: Browse nearby providers by category and location | G30: As a customer, I want to filter providers by category and distance without needing the AI conversation, so that basic discovery works end to end -- proving the platform's core value with zero dependency on verification-review turnaround or AI infrastructure being finished. This story delivers the first customer-facing search surface: a structured (non-conversational) directory backed by the geospatial proximity infrastructure (PostgreSQL earthdistance/cube) and the discoverability gate from VER-002. It is intentionally simpler than the eventual AI-powered results (MAT-001) and exists specifically to ship discovery early. Scope boundary: does not include the AI conversation (AI-001) or ranked AI-matched results (MAT-001) -- filtering here is a straightforward category + radius query. | H30: 1. earthdistance and cube PostgreSQL extensions are enabled via migration; GiST indexes exist on saved_addresses and service_areas location columns. 2. Search filters apply in order: category, then geospatial radius (using earth_box before earth_distance), then discoverability -- a provider with is_discoverable=false never appears in results regardless of category/distance fit. 3. Results show provider photo, name, category, rating with review count (never rating alone), and distance. 4. Empty results show a specific empty-state message distinct from a "no search performed yet" state. 5. Search Results screen is implemented in its structured (pre-AI) form, ready to be upgraded to AI-ranked results in MAT-001 without a screen redesign. 6. Query performance is verified to use the GiST index (via query plan check) rather than a sequential scan at representative data volumes. 7. Automated tests cover filter precedence (category to geo to discoverability) and deterministic tie-breaking when multiple providers are equally ranked. | I30: Critical | M30: ✅ Done | O30: CUS-002, PRO-002, VER-002 | P30: =IF(ISNUMBER(SEARCH("Done",M30)),1,IF(ISNUMBER(SEARCH("In Progress",M30)),0.5,0)) -> 1
A31: CLM-001 | B31: SP06 | C31: ML6-EP02 | D31: ML6 | E31: PH2 | F31: Claim my Google-seeded business listing | G31: As a business owner, I want to find my business among Google-seeded listings and verify I own the public phone number on record, so that I gain edit access to my own storefront instead of a stranger being able to claim it. This story bootstraps Business supply from public Google listings (so the directory isn't empty at launch) and implements the claim flow's OTP-against-public-record safeguard. Until claimed, these listings are flagged internally as unclaimed per the pending Google Places legal/ToS review, and must never be treated as equivalent to a verified, self-registered provider. Scope boundary: does not change how self-registered providers (PRO-001) are created -- this story only handles the separate unclaimed-listing import and claim path. | H31: 1. Import job creates providers rows with listing_source=google_seeded_unclaimed, is_claimed=false, and a populated google_place_id -- never marked as self_registered. 2. Unclaimed listings are visually distinct in search/directory results (a clearly visible "Unclaimed" label, not a small badge easy to miss). 3. Claim search screen lets a user find their business by name/location among unclaimed listings. 4. An OTP is sent to the public phone number on record for that listing -- never to a number the claimant types in themselves. 5. Successful OTP verification sets is_claimed=true, populates user_id with the claimant's Account, and routes the listing through the same Verification gate a self-registered Business would go through. 6. If OTP verification fails or the public number is unusable, the flow falls back to an explicit "this isn't working" admin-review path. 7. Once claimed, subsequent Google Places sync jobs never overwrite owner-edited fields -- imported data only backfills genuinely empty fields. 8. Automated tests cover: OTP-goes-only-to-public-number, and the admin-fallback path triggering correctly on OTP failure. | I31: Medium | M31: ✅ Done | O31: VER-002, DIR-001 | P31: =IF(ISNUMBER(SEARCH("Done",M31)),1,IF(ISNUMBER(SEARCH("In Progress",M31)),0.5,0)) -> 1
... A47: REL-002 | B47: SP15 | C47: ML15-EP01 | D47: ML15 | E47: PH4 | F47: Release the AI Marketplace MVP | G47: As a customer and provider, I want a production-ready AI Marketplace app, so that I can actually discover and offer local services on a live, supported platform. This is the final story of the roadmap: production deployment, monitoring/rollback readiness, app-store packaging, and operational handover, gated entirely on REL-001's validation passing first. Scope boundary: no new feature work happens in this story -- it is deployment and hand-off only. | H47: 1. Deployment to production is completed via the finalized CI/CD pipeline, with every Must-Have item from 11_MVP_SCOPE.md confirmed live. 2. Production monitoring and alerting are active before traffic is directed to the new release, with a documented rollback plan. 3. App-store (iOS/Android) release packaging is complete and submitted/approved per each store's requirements. 4. A release-notes document is published summarizing what shipped. 5. On-call/support handover is documented so post-release issues have a clear, immediate response path. 6. This story does not begin until REL-001 has been completed with no open release-blocking issues. | I47: Critical | M47: ⏳ Planned | O47: REL-001 | P47: =IF(ISNUMBER(SEARCH("Done",M47)),1,IF(ISNUMBER(SEARCH("In Progress",M47)),0.5,0)) -> 0
A48: CTG-001 | B48: SP07 | C48: ML7-EP03 | D48: ML7 | E48: PH2 | F48: Build the real Category domain and seed the v1 launch taxonomy | G48: As the engineering team, we need the real Category domain (category.categories, category.category_question_templates, and the real provider_categories join table) to exist and be seeded with the v1 launch taxonomy, so that AI-001's conversational intake has real categories and follow-up questions to resolve against instead of an interim workaround. This story builds the schema 04_DATABASE.md's Category Domain section already specifies and seeds it with the 14-category v1 launch taxonomy locked in docs/AI/17_CATEGORY_TAXONOMY.md (13_OPEN_DECISIONS.md item 1). It does not reconcile PRO-002's existing free-text provider_category_labels into the new real categories, and does not change how providers select categories today -- migrating provider-facing category selection to the real domain is a separate, future decision. Scope boundary: no AI conversation logic (that's AI-001/AI-002). No change to provider_category_labels or DIR-001's existing search matching. | H48: 1. Migration creates category.categories, category.category_question_templates, and category.provider_categories exactly per 04_DATABASE.md's Category Domain section (self-referential parent_category_id, JSONB options, composite PK on provider_categories). 2. Migration seeds category.categories with the 14 categories from docs/AI/17_CATEGORY_TAXONOMY.md (slug, name, name_ar, sort_order). 3. Migration seeds category.category_question_templates with every follow-up question listed in docs/AI/17_CATEGORY_TAXONOMY.md (question_text, question_text_ar, question_type, options, is_required, sort_order). 4. Seed data is idempotent -- running the migration's upgrade twice, or an upgrade/downgrade/upgrade cycle, never creates duplicate category or question-template rows. 5. A read-only service method (or endpoint, if warranted) exposes the seeded categories and their question templates so AI-001 can consume them once built. 6. provider_category_labels and DIR-001's existing search query are completely unmodified -- this story adds a new, independent domain without changing provider-facing category behavior. 7. Automated tests cover: migration upgrade/downgrade, seed data completeness (14 categories, correct per-category question counts), and idempotency. | I48: Critical | M48: ✅ Done | P48: =IF(ISNUMBER(SEARCH("Done",M48)),1,IF(ISNUMBER(SEARCH("In Progress",M48)),0.5,0)) -> 1

Sheet Releases
A1: Release ID | B1: Version | C1: Release Name | D1: Target Date | E1: Actual Date | F1: Milestones Included | G1: Status | H1: Notes
A2: REL-01 | B2: v1.0 | C2: AI Marketplace MVP Release | F2: ML1-ML15 | G2: Planned | H2: First production release covering the approved MVP scope.

Sheet Decision_Log
A1: Decision ID | B1: Title | C1: Summary | D1: Status | E1: Date | F1: Reference
