Workbook

Sheet Dashboard
A1: MyCommunity — Project Dashboard
A2: Live rollup from Phase Tracker, Milestones, Epics, Sprints, Stories, Releases & Risks. Nothing here needs manual updating.
A4: → Phase Tracker | B4: → Milestones | C4: → Epics | D4: → Sprints | E4: → Stories | F4: → Releases | G4: → Risks | H4: → Decision_Log
A6: Metric | B6: Value | C6: Target | D6: Status | F6: Chart Data — Phase Progress | I6: Chart Data — Story Status
A7: Overall Progress | B7: =SUMPRODUCT('Phase Tracker'!$E$2:$E$7,'Phase Tracker'!$D$2:$D$7) -> 0.1 | C7: 1 | D7: =IF(B7=1,"✅ Completed","🔄 In Progress") -> 🔄 In Progress | F7: Phase | G7: Progress % | I7: ✅ Done | J7: =COUNTIF(Stories!$L$2:L$200,"*Done*") -> 18
A8: Current Phase | B8: =IFERROR(INDEX('Phase Tracker'!$A$2:$A$7,MATCH(TRUE(),INDEX('Phase Tracker'!$E$2:$E$7<1,0),0)),"All Phases Complete") -> PH2 | F8: ='Phase Tracker'!B2 -> Platform Foundation | G8: ='Phase Tracker'!E2 -> 1 | I8: 🔄 In Progress | J8: =COUNTIF(Stories!$L$2:L$200,"*In Progress*") -> 0
A9: Current Milestone | B9: =IFERROR(INDEX(Milestones!$B$2:$B$25,MATCH(1,INDEX((Milestones!$C$2:$C$25=B8)*(Milestones!$J$2:$J$25<1),0),0)),"All Milestones Complete") -> ML2 | F9: ='Phase Tracker'!B3 -> Feature Delivery (Vertical Slices) | G9: ='Phase Tracker'!E3 -> 0 | I9: 🚫 Blocked | J9: =COUNTIF(Stories!$L$2:L$200,"*Blocked*") -> 0
A10: Current Sprint | B10: =IFERROR(INDEX(Sprints!$A$2:$A$26,MATCH(TRUE(),INDEX(Sprints!$I$2:$I$26<1,0),0)),"All Sprints Complete") -> SP02 | F10: ='Phase Tracker'!B4 -> Production Readiness | G10: ='Phase Tracker'!E4 -> 0 | I10: ⏳ Not Started | J10: =COUNTIF(Stories!$L$2:L$200,"*Not Started*") -> 0
A11: Completed Phases | B11: =COUNTIF('Phase Tracker'!$F$2:$F$7,"*Completed*") -> 1 | C11: =COUNTA('Phase Tracker'!$A$2:$A$7) -> 4 | D11: =IF(B11=C11,"✅ Completed","🔄 In Progress") -> 🔄 In Progress | F11: ='Phase Tracker'!B5 -> MVP Release | G11: ='Phase Tracker'!E5 -> 0
A12: Completed Milestones | B12: =COUNTIF(Milestones!$K$2:$K$25,"*Completed*") -> 1 | C12: =COUNTA(Milestones!$B$2:$B$25) -> 24 | D12: =IF(B12=C12,"✅ Completed","🔄 In Progress") -> 🔄 In Progress | F12: ='Phase Tracker'!B6 -> 0 | G12: ='Phase Tracker'!E6 -> 0
A13: Completed Epics | B13: =COUNTIF(Epics!$K$2:K$100,"*Completed*") -> 1 | C13: =COUNTA(Epics!$C$2:C$100) -> 60 | D13: =IF(B13=C13,"✅ Completed","🔄 In Progress") -> 🔄 In Progress | F13: ='Phase Tracker'!B7 -> 0 | G13: ='Phase Tracker'!E7 -> 0
A14: Completed Stories | B14: =COUNTIF(Stories!$L$2:L$200,"*Done*") -> 18 | C14: =B15 -> 124 | D14: =IF(B14=C14,"✅ Completed","🔄 In Progress") -> 🔄 In Progress
A15: Total Stories | B15: =COUNTA(Stories!$A$2:A$200) -> 124
A16: Current Release | B16: =Releases!$B$2&" – "&Releases!$C$2&" ("&Releases!$G$2&")" -> v1.0 – MyCommunity MVP Release (Planned)
A17: Project Health | B17: =IF(SUM(COUNTIF('Phase Tracker'!$F$2:$F$7,"*Blocked*"),COUNTIF(Milestones!$K$2:$K$25,"*Blocked*"),COUNTIF(Epics!$K$2:K$100,"*Blocked*"),COUNTIF(Sprints!$J$2:$J$26,"*Blocked*"),COUNTIF(Stories!$L$2:L$200,"*Blocked*"))>0,"🔴 At Risk",IF(B7=1,"🟢 Complete","🟢 On Track")) -> 🟢 On Track
A18: Upcoming Sprint | B18: =IFERROR(INDEX(Sprints!$A$2:$A$26,MATCH(B10,Sprints!$A$2:$A$26,0)+1),"N/A") -> SP03
A19: Blocked Stories | B19: =COUNTIF(Stories!$L$2:L$200,"*Blocked*") -> 0 | C19: 0 | D19: =IF(B19=0,"✅ Good","🚫 Blocked") -> ✅ Good
A20: Open Risks | B20: =COUNTIF(Risks!$H$2:$H$200,"Open") -> 0 | C20: 0 | D20: =IF(B20=0,"✅ Good","🔴 At Risk") -> ✅ Good
A21: Overall Completion % | B21: =B7 -> 0.1 | C21: 1 | D21: =IF(B21=1,"✅ Completed","🔄 In Progress") -> 🔄 In Progress
A24: Total Project Spend (AED) | B24: =Expenses!H5 -> 134.633

Sheet Phase Tracker
A1: Phase ID | B1: Phase | C1: Description | D1: Weight | E1: Progress % | F1: Status
A2: PH1 | B2: Platform Foundation | C2: Establish the engineering platform, backend foundation, development standards, tooling, testing framework, documentation, and shared infrastructure. | D2: 0.1 | E2: 1 | F2: ✅ Completed
A3: PH2 | B3: Feature Delivery (Vertical Slices) | C3: Deliver every resident- and admin-facing capability as a complete vertical slice: data model, backend API, third-party integration (Firebase, media, push), Flutter UI, and tests — so each sprint ships something usable end to end. | D3: 0.65 | E3: 0 | F3: ⏳ Planned
A4: PH3 | B4: Production Readiness | C4: Complete performance optimization, security hardening, DevOps, monitoring, testing, deployment automation, and operational readiness. | D4: 0.2 | E4: 0 | F4: ⏳ Planned
A5: PH4 | B5: MVP Release | C5: Complete final validation, production deployment, documentation, and official MVP release. | D5: 0.05 | E5: 0 | F5: ⏳ Planned

Sheet Milestones
A1: Sr No | B1: ID | C1: Phase ID | D1: Milestone | E1: Description | F1: Start Date | G1: Target Date | H1: Actual Completion | I1: Owner | J1: Progress % | K1: Status | L1: Hours Spent
A2: 1 | B2: ML1 | C2: PH1 | D2: Backend Foundation | E2: Establish the production-ready backend platform, engineering standards, tooling, testing, documentation, and shared infrastructure. | F2: 46206 | G2: 46206 | H2: Shri | I2: 17 | J2: =IFERROR(AVERAGEIF(Epics!$B$2:B$100,B2,Epics!$J$2:J$100),0) -> 1 | K2: =IF(COUNTIFS(Epics!$B$2:B$100,B2,Epics!$K$2:K$100,"*Blocked*")>0,"🚫 Blocked",IF(J2=1,"✅ Completed",IF(J2>0,"🔄 In Progress","⏳ Planned"))) -> ✅ Completed | L2: =IF(SUMIF(Stories!$D$2:D$200,B2,Stories!$J$2:J$200)=0,IF(B2="ML1",17,0),SUMIF(Stories!$D$2:D$200,B2,Stories!$J$2:J$200)) -> 17
A3: 2 | B3: ML2 | C3: PH2 | D3: Identity & Authentication | E3: Implement secure registration, login, authentication, authorization, and session management. | J3: =IFERROR(AVERAGEIF(Epics!$B$2:B$100,B3,Epics!$J$2:J$100),0) -> 0 | K3: =IF(COUNTIFS(Epics!$B$2:B$100,B3,Epics!$K$2:K$100,"*Blocked*")>0,"🚫 Blocked",IF(J3=1,"✅ Completed",IF(J3>0,"🔄 In Progress","⏳ Planned"))) -> ⏳ Planned | L3: =IF(SUMIF(Stories!$D$2:D$200,B3,Stories!$J$2:J$200)=0,IF(B3="ML1",17,0),SUMIF(Stories!$D$2:D$200,B3,Stories!$J$2:J$200)) -> 0
A4: 3 | B4: ML3 | C4: PH2 | D4: Resident Verification | E4: Implement email, mobile, community, and resident verification workflows. | J4: =IFERROR(AVERAGEIF(Epics!$B$2:B$100,B4,Epics!$J$2:J$100),0) -> 0 | K4: =IF(COUNTIFS(Epics!$B$2:B$100,B4,Epics!$K$2:K$100,"*Blocked*")>0,"🚫 Blocked",IF(J4=1,"✅ Completed",IF(J4>0,"🔄 In Progress","⏳ Planned"))) -> ⏳ Planned | L4: =IF(SUMIF(Stories!$D$2:D$200,B4,Stories!$J$2:J$200)=0,IF(B4="ML1",17,0),SUMIF(Stories!$D$2:D$200,B4,Stories!$J$2:J$200)) -> 0
A5: 4 | B5: ML4 | C5: PH2 | D5: Resident Profile | E5: Build resident profiles, preferences, privacy settings, and account management. | J5: =IFERROR(AVERAGEIF(Epics!$B$2:B$100,B5,Epics!$J$2:J$100),0) -> 0 | K5: =IF(COUNTIFS(Epics!$B$2:B$100,B5,Epics!$K$2:K$100,"*Blocked*")>0,"🚫 Blocked",IF(J5=1,"✅ Completed",IF(J5>0,"🔄 In Progress","⏳ Planned"))) -> ⏳ Planned | L5: =IF(SUMIF(Stories!$D$2:D$200,B5,Stories!$J$2:J$200)=0,IF(B5="ML1",17,0),SUMIF(Stories!$D$2:D$200,B5,Stories!$J$2:J$200)) -> 0
A6: 5 | B6: ML5 | C6: PH2 | D6: Community Foundation | E6: Implement community management, membership, invitations, roles, and administration. | J6: =IFERROR(AVERAGEIF(Epics!$B$2:B$100,B6,Epics!$J$2:J$100),0) -> 0 | K6: =IF(COUNTIFS(Epics!$B$2:B$100,B6,Epics!$K$2:K$100,"*Blocked*")>0,"🚫 Blocked",IF(J6=1,"✅ Completed",IF(J6>0,"🔄 In Progress","⏳ Planned"))) -> ⏳ Planned | L6: =IF(SUMIF(Stories!$D$2:D$200,B6,Stories!$J$2:J$200)=0,IF(B6="ML1",17,0),SUMIF(Stories!$D$2:D$200,B6,Stories!$J$2:J$200)) -> 0
A7: 6 | B7: ML6 | C7: PH2 | D7: Community Feed | E7: Enable posts, comments, reactions, attachments, hashtags, and mentions. | J7: =IFERROR(AVERAGEIF(Epics!$B$2:B$100,B7,Epics!$J$2:J$100),0) -> 0 | K7: =IF(COUNTIFS(Epics!$B$2:B$100,B7,Epics!$K$2:K$100,"*Blocked*")>0,"🚫 Blocked",IF(J7=1,"✅ Completed",IF(J7>0,"🔄 In Progress","⏳ Planned"))) -> ⏳ Planned | L7: =IF(SUMIF(Stories!$D$2:D$200,B7,Stories!$J$2:J$200)=0,IF(B7="ML1",17,0),SUMIF(Stories!$D$2:D$200,B7,Stories!$J$2:J$200)) -> 0
A8: 7 | B8: ML7 | C8: PH2 | D8: Community Engagement | E8: Implement announcements, quick reactions, bookmarks, reporting, and engagement enhancements. | J8: =IFERROR(AVERAGEIF(Epics!$B$2:B$100,B8,Epics!$J$2:J$100),0) -> 0 | K8: =IF(COUNTIFS(Epics!$B$2:B$100,B8,Epics!$K$2:K$100,"*Blocked*")>0,"🚫 Blocked",IF(J8=1,"✅ Completed",IF(J8>0,"🔄 In Progress","⏳ Planned"))) -> ⏳ Planned | L8: =IF(SUMIF(Stories!$D$2:D$200,B8,Stories!$J$2:J$200)=0,IF(B8="ML1",17,0),SUMIF(Stories!$D$2:D$200,B8,Stories!$J$2:J$200)) -> 0
A9: 8 | B9: ML8 | C9: PH2 | D9: Community Events | E9: Build event creation, discovery, RSVPs, attendance, and event management. | J9: =IFERROR(AVERAGEIF(Epics!$B$2:B$100,B9,Epics!$J$2:J$100),0) -> 0 | K9: =IF(COUNTIFS(Epics!$B$2:B$100,B9,Epics!$K$2:K$100,"*Blocked*")>0,"🚫 Blocked",IF(J9=1,"✅ Completed",IF(J9>0,"🔄 In Progress","⏳ Planned"))) -> ⏳ Planned | L9: =IF(SUMIF(Stories!$D$2:D$200,B9,Stories!$J$2:J$200)=0,IF(B9="ML1",17,0),SUMIF(Stories!$D$2:D$200,B9,Stories!$J$2:J$200)) -> 0
A10: 9 | B10: ML9 | C10: PH2 | D10: Help & Humanity | E10: Deliver Help Requests, Lost & Found, Blood Donation, Emergency Assistance, and Volunteer support. | J10: =IFERROR(AVERAGEIF(Epics!$B$2:B$100,B10,Epics!$J$2:J$100),0) -> 0 | K10: =IF(COUNTIFS(Epics!$B$2:B$100,B10,Epics!$K$2:K$100,"*Blocked*")>0,"🚫 Blocked",IF(J10=1,"✅ Completed",IF(J10>0,"🔄 In Progress","⏳ Planned"))) -> ⏳ Planned | L10: =IF(SUMIF(Stories!$D$2:D$200,B10,Stories!$J$2:J$200)=0,IF(B10="ML1",17,0),SUMIF(Stories!$D$2:D$200,B10,Stories!$J$2:J$200)) -> 0
A11: 10 | B11: ML10 | C11: PH2 | D11: Notifications | E11: Implement push notifications, in-app notifications, notification preferences, and delivery tracking. | J11: =IFERROR(AVERAGEIF(Epics!$B$2:B$100,B11,Epics!$J$2:J$100),0) -> 0 | K11: =IF(COUNTIFS(Epics!$B$2:B$100,B11,Epics!$K$2:K$100,"*Blocked*")>0,"🚫 Blocked",IF(J11=1,"✅ Completed",IF(J11>0,"🔄 In Progress","⏳ Planned"))) -> ⏳ Planned | L11: =IF(SUMIF(Stories!$D$2:D$200,B11,Stories!$J$2:J$200)=0,IF(B11="ML1",17,0),SUMIF(Stories!$D$2:D$200,B11,Stories!$J$2:J$200)) -> 0
A12: 11 | B12: ML11 | C12: PH2 | D12: Search & Discovery | E12: Implement global search, filtering, sorting, and content discovery across supported modules. | J12: =IFERROR(AVERAGEIF(Epics!$B$2:B$100,B12,Epics!$J$2:J$100),0) -> 0 | K12: =IF(COUNTIFS(Epics!$B$2:B$100,B12,Epics!$K$2:K$100,"*Blocked*")>0,"🚫 Blocked",IF(J12=1,"✅ Completed",IF(J12>0,"🔄 In Progress","⏳ Planned"))) -> ⏳ Planned | L12: =IF(SUMIF(Stories!$D$2:D$200,B12,Stories!$J$2:J$200)=0,IF(B12="ML1",17,0),SUMIF(Stories!$D$2:D$200,B12,Stories!$J$2:J$200)) -> 0
A13: 12 | B13: ML12 | C13: PH2 | D13: Moderation & Trust | E13: Implement reporting, moderation workflows, warnings, suspensions, bans, and audit support. | J13: =IFERROR(AVERAGEIF(Epics!$B$2:B$100,B13,Epics!$J$2:J$100),0) -> 0 | K13: =IF(COUNTIFS(Epics!$B$2:B$100,B13,Epics!$K$2:K$100,"*Blocked*")>0,"🚫 Blocked",IF(J13=1,"✅ Completed",IF(J13>0,"🔄 In Progress","⏳ Planned"))) -> ⏳ Planned | L13: =IF(SUMIF(Stories!$D$2:D$200,B13,Stories!$J$2:J$200)=0,IF(B13="ML1",17,0),SUMIF(Stories!$D$2:D$200,B13,Stories!$J$2:J$200)) -> 0
A14: 13 | B14: ML13 | C14: PH2 | D14: Administration Portal | E14: Develop administrative tools, dashboards, feature flags, system configuration, and audit management. | J14: =IFERROR(AVERAGEIF(Epics!$B$2:B$100,B14,Epics!$J$2:J$100),0) -> 0 | K14: =IF(COUNTIFS(Epics!$B$2:B$100,B14,Epics!$K$2:K$100,"*Blocked*")>0,"🚫 Blocked",IF(J14=1,"✅ Completed",IF(J14>0,"🔄 In Progress","⏳ Planned"))) -> ⏳ Planned | L14: =IF(SUMIF(Stories!$D$2:D$200,B14,Stories!$J$2:J$200)=0,IF(B14="ML1",17,0),SUMIF(Stories!$D$2:D$200,B14,Stories!$J$2:J$200)) -> 0
... A25: 24 | B25: ML24 | C25: PH4 | D25: MVP Release v1.0 | E25: Deliver the first production-ready release of MyCommunity with all approved MVP functionality deployed and documented. | J25: =IFERROR(AVERAGEIF(Epics!$B$2:B$100,B25,Epics!$J$2:J$100),0) -> 0 | K25: =IF(COUNTIFS(Epics!$B$2:B$100,B25,Epics!$K$2:K$100,"*Blocked*")>0,"🚫 Blocked",IF(J25=1,"✅ Completed",IF(J25>0,"🔄 In Progress","⏳ Planned"))) -> ⏳ Planned | L25: =IF(SUMIF(Stories!$D$2:D$200,B25,Stories!$J$2:J$200)=0,IF(B25="ML1",17,0),SUMIF(Stories!$D$2:D$200,B25,Stories!$J$2:J$200)) -> 0

Sheet Epics
A1: Sr No | B1: Milestone ID | C1: Epic Code | D1: Epic | E1: Description | F1: Owner | G1: Start Date | H1: Target Date | I1: Actual Completion | J1: Progress % | K1: Status
A2: 1 | B2: ML1 | C2: ML1-EP01 | D2: Backend Foundation | E2: Establish the complete backend engineering platform and shared infrastructure. | J2: =IFERROR(AVERAGEIF(Stories!$C$2:C$200,C2,Stories!$O$2:O$200),0)/100 -> 1 | K2: =IF(COUNTIFS(Stories!$C$2:C$200,C2,Stories!$L$2:L$200,"*Blocked*")>0,"🚫 Blocked",IF(J2=1,"✅ Completed",IF(J2>0,"🔄 In Progress","⏳ Planned"))) -> ✅ Completed
A3: 2 | B3: ML2 | C3: ML2-EP01 | D3: User Registration | E3: Enable secure resident account registration. | J3: =IFERROR(AVERAGEIF(Stories!$C$2:C$200,C3,Stories!$O$2:O$200),0)/100 -> 0 | K3: =IF(COUNTIFS(Stories!$C$2:C$200,C3,Stories!$L$2:L$200,"*Blocked*")>0,"🚫 Blocked",IF(J3=1,"✅ Completed",IF(J3>0,"🔄 In Progress","⏳ Planned"))) -> ⏳ Planned
A4: 3 | B4: ML2 | C4: ML2-EP02 | D4: User Authentication | E4: Implement login, logout and authentication workflows. | J4: =IFERROR(AVERAGEIF(Stories!$C$2:C$200,C4,Stories!$O$2:O$200),0)/100 -> 0 | K4: =IF(COUNTIFS(Stories!$C$2:C$200,C4,Stories!$L$2:L$200,"*Blocked*")>0,"🚫 Blocked",IF(J4=1,"✅ Completed",IF(J4>0,"🔄 In Progress","⏳ Planned"))) -> ⏳ Planned
A5: 4 | B5: ML2 | C5: ML2-EP03 | D5: Session Management | E5: Manage JWT access tokens, refresh tokens and active sessions. | J5: =IFERROR(AVERAGEIF(Stories!$C$2:C$200,C5,Stories!$O$2:O$200),0)/100 -> 0 | K5: =IF(COUNTIFS(Stories!$C$2:C$200,C5,Stories!$L$2:L$200,"*Blocked*")>0,"🚫 Blocked",IF(J5=1,"✅ Completed",IF(J5>0,"🔄 In Progress","⏳ Planned"))) -> ⏳ Planned
A6: 5 | B6: ML2 | C6: ML2-EP04 | D6: Authorization | E6: Implement roles, permissions and access control. | J6: =IFERROR(AVERAGEIF(Stories!$C$2:C$200,C6,Stories!$O$2:O$200),0)/100 -> 0 | K6: =IF(COUNTIFS(Stories!$C$2:C$200,C6,Stories!$L$2:L$200,"*Blocked*")>0,"🚫 Blocked",IF(J6=1,"✅ Completed",IF(J6>0,"🔄 In Progress","⏳ Planned"))) -> ⏳ Planned
A7: 6 | B7: ML2 | C7: ML2-EP05 | D7: Password Management | E7: Support password creation, reset and account recovery. | J7: =IFERROR(AVERAGEIF(Stories!$C$2:C$200,C7,Stories!$O$2:O$200),0)/100 -> 0 | K7: =IF(COUNTIFS(Stories!$C$2:C$200,C7,Stories!$L$2:L$200,"*Blocked*")>0,"🚫 Blocked",IF(J7=1,"✅ Completed",IF(J7>0,"🔄 In Progress","⏳ Planned"))) -> ⏳ Planned
A8: 7 | B8: ML3 | C8: ML3-EP01 | D8: Email Verification | E8: Verify resident email addresses. | J8: =IFERROR(AVERAGEIF(Stories!$C$2:C$200,C8,Stories!$O$2:O$200),0)/100 -> 0 | K8: =IF(COUNTIFS(Stories!$C$2:C$200,C8,Stories!$L$2:L$200,"*Blocked*")>0,"🚫 Blocked",IF(J8=1,"✅ Completed",IF(J8>0,"🔄 In Progress","⏳ Planned"))) -> ⏳ Planned
A9: 8 | B9: ML3 | C9: ML3-EP02 | D9: Mobile Verification | E9: Verify resident mobile numbers using OTP. | J9: =IFERROR(AVERAGEIF(Stories!$C$2:C$200,C9,Stories!$O$2:O$200),0)/100 -> 0 | K9: =IF(COUNTIFS(Stories!$C$2:C$200,C9,Stories!$L$2:L$200,"*Blocked*")>0,"🚫 Blocked",IF(J9=1,"✅ Completed",IF(J9>0,"🔄 In Progress","⏳ Planned"))) -> ⏳ Planned
A10: 9 | B10: ML3 | C10: ML3-EP03 | D10: Residency Verification | E10: Support community, Ejari and DEWA verification workflows. | J10: =IFERROR(AVERAGEIF(Stories!$C$2:C$200,C10,Stories!$O$2:O$200),0)/100 -> 0 | K10: =IF(COUNTIFS(Stories!$C$2:C$200,C10,Stories!$L$2:L$200,"*Blocked*")>0,"🚫 Blocked",IF(J10=1,"✅ Completed",IF(J10>0,"🔄 In Progress","⏳ Planned"))) -> ⏳ Planned
A11: 10 | B11: ML4 | C11: ML4-EP01 | D11: Resident Profile | E11: Manage resident personal information. | J11: =IFERROR(AVERAGEIF(Stories!$C$2:C$200,C11,Stories!$O$2:O$200),0)/100 -> 0 | K11: =IF(COUNTIFS(Stories!$C$2:C$200,C11,Stories!$L$2:L$200,"*Blocked*")>0,"🚫 Blocked",IF(J11=1,"✅ Completed",IF(J11>0,"🔄 In Progress","⏳ Planned"))) -> ⏳ Planned
A12: 11 | B12: ML4 | C12: ML4-EP02 | D12: Privacy & Preferences | E12: Manage privacy settings and user preferences. | J12: =IFERROR(AVERAGEIF(Stories!$C$2:C$200,C12,Stories!$O$2:O$200),0)/100 -> 0 | K12: =IF(COUNTIFS(Stories!$C$2:C$200,C12,Stories!$L$2:L$200,"*Blocked*")>0,"🚫 Blocked",IF(J12=1,"✅ Completed",IF(J12>0,"🔄 In Progress","⏳ Planned"))) -> ⏳ Planned
A13: 12 | B13: ML5 | C13: ML5-EP01 | D13: Community Management | E13: Create and manage residential communities. | J13: =IFERROR(AVERAGEIF(Stories!$C$2:C$200,C13,Stories!$O$2:O$200),0)/100 -> 0 | K13: =IF(COUNTIFS(Stories!$C$2:C$200,C13,Stories!$L$2:L$200,"*Blocked*")>0,"🚫 Blocked",IF(J13=1,"✅ Completed",IF(J13>0,"🔄 In Progress","⏳ Planned"))) -> ⏳ Planned
... A58: 57 | B58: ML24 | C58: ML24-EP01 | D58: MVP Release Deployment | E58: Deploy and finalize the first production-ready MVP release. | J58: =IFERROR(AVERAGEIF(Stories!$C$2:C$200,C58,Stories!$O$2:O$200),0)/100 -> 0 | K58: =IF(COUNTIFS(Stories!$C$2:C$200,C58,Stories!$L$2:L$200,"*Blocked*")>0,"🚫 Blocked",IF(J58=1,"✅ Completed",IF(J58>0,"🔄 In Progress","⏳ Planned"))) -> ⏳ Planned
A59: 58 | B59: ML9 | C59: ML9-EP04 | D59: Help & Humanity UI | E59: Build the Flutter experience for Help Requests, Lost & Found, and Humanity Acts. | J59: =IFERROR(AVERAGEIF(Stories!$C$2:$C$500,C59,Stories!$O$2:$O$500),0)/100 -> 0 | K59: =IF(COUNTIFS(Stories!$C$2:$C$500,C59,Stories!$L$2:$L$500,"*Blocked*")>0,"🚫 Blocked",IF(J59=1,"✅ Completed",IF(J59>0,"🔄 In Progress","⏳ Planned"))) -> ⏳ Planned
A60: 59 | B60: ML11 | C60: ML11-EP03 | D60: Search UI | E60: Build the Flutter global search experience across residents, posts, communities, events and help requests. | J60: =IFERROR(AVERAGEIF(Stories!$C$2:$C$500,C60,Stories!$O$2:$O$500),0)/100 -> 0 | K60: =IF(COUNTIFS(Stories!$C$2:$C$500,C60,Stories!$L$2:$L$500,"*Blocked*")>0,"🚫 Blocked",IF(J60=1,"✅ Completed",IF(J60>0,"🔄 In Progress","⏳ Planned"))) -> ⏳ Planned
A61: 60 | B61: ML12 | C61: ML12-EP04 | D61: Moderation UI (Admin) | E61: Build the admin-facing moderation queue and enforcement UI. | J61: =IFERROR(AVERAGEIF(Stories!$C$2:$C$500,C61,Stories!$O$2:$O$500),0)/100 -> 0 | K61: =IF(COUNTIFS(Stories!$C$2:$C$500,C61,Stories!$L$2:$L$500,"*Blocked*")>0,"🚫 Blocked",IF(J61=1,"✅ Completed",IF(J61>0,"🔄 In Progress","⏳ Planned"))) -> ⏳ Planned

Sheet Sprints
A1: Sprint ID | B1: Sprint | C1: Theme | D1: Goal | E1: Start Date | F1: End Date | G1: Planned Stories | H1: Completed Stories | I1: Progress % | J1: Status | K1: Milestones | L1: Phases | M1: Summary Document
A2: SP01 | B2: Sprint 1 | C2: Backend Foundation | D2: Establish the production-ready backend engineering platform and shared infrastructure. | G2: 18 | H2: =COUNTIFS(Stories!$B$2:B$200,A2,Stories!$L$2:L$200,"*Done*") -> 18 | I2: =IFERROR(AVERAGEIFS(Stories!$O$2:O$200,Stories!$B$2:B$200,A2),0)/100 -> 1 | J2: =IF(COUNTIFS(Stories!$B$2:B$200,A2,Stories!$L$2:L$200,"*Blocked*")>0,"🚫 Blocked",IF(I2=1,"✅ Completed",IF(I2>0,"🔄 In Progress","⏳ Planned"))) -> ✅ Completed | K2: {=_xlfn.TEXTJOIN(", ",TRUE(),IF(Sprint_Epics!$A$2:$A$200=A2,Sprint_Epics!$C$2:$C$200,""))} -> ML1 | L2: {=_xlfn.TEXTJOIN(", ",TRUE(),IF(Sprint_Epics!$A$2:$A$200=A2,IFERROR(INDEX(Milestones!$C$2:$C$25,MATCH(Sprint_Epics!$C$2:$C$200,Milestones!$B$2:$B$25,0)),""),""))} -> PH1
A3: SP02 | B3: Sprint 2 | C3: Account Registration & Login | D3: Deliver a complete Firebase-based registration and login flow, backend and mobile UI together, so a resident can actually create an account and sign in by the end of this sprint. | G3: 7 | H3: =COUNTIFS(Stories!$B$2:$B$500,A3,Stories!$L$2:$L$500,"*Done*") -> 0 | I3: =IFERROR(AVERAGEIFS(Stories!$O$2:$O$500,Stories!$B$2:$B$500,A3),0)/100 -> 0 | J3: =IF(COUNTIFS(Stories!$B$2:$B$500,A3,Stories!$L$2:$L$500,"*Blocked*")>0,"🚫 Blocked",IF(I3=1,"✅ Completed",IF(I3>0,"🔄 In Progress","⏳ Planned"))) -> ⏳ Planned | K3: {=_xlfn.TEXTJOIN(", ",TRUE(),IF(Sprint_Epics!$A$2:$A$500=A3,Sprint_Epics!$C$2:$C$500,""))} -> ML2, ML2, ML14, ML15 | L3: {=_xlfn.TEXTJOIN(", ",TRUE(),IF(Sprint_Epics!$A$2:$A$500=A3,IFERROR(INDEX(Milestones!$C$2:$C$25,MATCH(Sprint_Epics!$C$2:$C$500,Milestones!$B$2:$B$25,0)),""),""))} -> PH1, PH1, PH1, PH1
A4: SP03 | B4: Sprint 3 | C4: Account Security - Sessions & Authorization | D4: Let a resident see and manage their active sessions, and give the backend a working role/permission model, end to end. | G4: 4 | H4: =COUNTIFS(Stories!$B$2:$B$500,A4,Stories!$L$2:$L$500,"*Done*") -> 0 | I4: =IFERROR(AVERAGEIFS(Stories!$O$2:$O$500,Stories!$B$2:$B$500,A4),0)/100 -> 0 | J4: =IF(COUNTIFS(Stories!$B$2:$B$500,A4,Stories!$L$2:$L$500,"*Blocked*")>0,"🚫 Blocked",IF(I4=1,"✅ Completed",IF(I4>0,"🔄 In Progress","⏳ Planned"))) -> ⏳ Planned | K4: {=_xlfn.TEXTJOIN(", ",TRUE(),IF(Sprint_Epics!$A$2:$A$500=A4,Sprint_Epics!$C$2:$C$500,""))} -> ML2, ML2, ML16 | L4: {=_xlfn.TEXTJOIN(", ",TRUE(),IF(Sprint_Epics!$A$2:$A$500=A4,IFERROR(INDEX(Milestones!$C$2:$C$25,MATCH(Sprint_Epics!$C$2:$C$500,Milestones!$B$2:$B$25,0)),""),""))} -> PH1, PH1, PH1
A5: SP04 | B5: Sprint 4 | C5: Account Recovery & Email Verification | D5: Let a resident add and verify an email address for account recovery and communication, matching the MVP scope's 'Email Verification' requirement. | G5: 4 | H5: =COUNTIFS(Stories!$B$2:$B$500,A5,Stories!$L$2:$L$500,"*Done*") -> 0 | I5: =IFERROR(AVERAGEIFS(Stories!$O$2:$O$500,Stories!$B$2:$B$500,A5),0)/100 -> 0 | J5: =IF(COUNTIFS(Stories!$B$2:$B$500,A5,Stories!$L$2:$L$500,"*Blocked*")>0,"🚫 Blocked",IF(I5=1,"✅ Completed",IF(I5>0,"🔄 In Progress","⏳ Planned"))) -> ⏳ Planned | K5: {=_xlfn.TEXTJOIN(", ",TRUE(),IF(Sprint_Epics!$A$2:$A$500=A5,Sprint_Epics!$C$2:$C$500,""))} -> ML2, ML3, ML16 | L5: {=_xlfn.TEXTJOIN(", ",TRUE(),IF(Sprint_Epics!$A$2:$A$500=A5,IFERROR(INDEX(Milestones!$C$2:$C$25,MATCH(Sprint_Epics!$C$2:$C$500,Milestones!$B$2:$B$25,0)),""),""))} -> PH1, PH1, PH1
A6: SP05 | B6: Sprint 5 | C6: Residency Verification - Ejari & DEWA | D6: Let a resident upload their Ejari and DEWA documents and track verification status end to end. (Mobile-number verification, ML3-EP02, is already satisfied by Sprint 2's Firebase OTP flow.) | G6: 4 | H6: =COUNTIFS(Stories!$B$2:$B$500,A6,Stories!$L$2:$L$500,"*Done*") -> 0 | I6: =IFERROR(AVERAGEIFS(Stories!$O$2:$O$500,Stories!$B$2:$B$500,A6),0)/100 -> 0 | J6: =IF(COUNTIFS(Stories!$B$2:$B$500,A6,Stories!$L$2:$L$500,"*Blocked*")>0,"🚫 Blocked",IF(I6=1,"✅ Completed",IF(I6>0,"🔄 In Progress","⏳ Planned"))) -> ⏳ Planned | K6: {=_xlfn.TEXTJOIN(", ",TRUE(),IF(Sprint_Epics!$A$2:$A$500=A6,Sprint_Epics!$C$2:$C$500,""))} -> ML3, ML16 | L6: {=_xlfn.TEXTJOIN(", ",TRUE(),IF(Sprint_Epics!$A$2:$A$500=A6,IFERROR(INDEX(Milestones!$C$2:$C$25,MATCH(Sprint_Epics!$C$2:$C$500,Milestones!$B$2:$B$25,0)),""),""))} -> PH1, PH1
A7: SP06 | B7: Sprint 6 | C7: Resident Profile | D7: Let a resident view and edit their profile (name, photo, bio, interests) end to end, per the MVP scope's Profile requirements. | G7: 4 | H7: =COUNTIFS(Stories!$B$2:$B$500,A7,Stories!$L$2:$L$500,"*Done*") -> 0 | I7: =IFERROR(AVERAGEIFS(Stories!$O$2:$O$500,Stories!$B$2:$B$500,A7),0)/100 -> 0 | J7: =IF(COUNTIFS(Stories!$B$2:$B$500,A7,Stories!$L$2:$L$500,"*Blocked*")>0,"🚫 Blocked",IF(I7=1,"✅ Completed",IF(I7>0,"🔄 In Progress","⏳ Planned"))) -> ⏳ Planned | K7: {=_xlfn.TEXTJOIN(", ",TRUE(),IF(Sprint_Epics!$A$2:$A$500=A7,Sprint_Epics!$C$2:$C$500,""))} -> ML4, ML16 | L7: {=_xlfn.TEXTJOIN(", ",TRUE(),IF(Sprint_Epics!$A$2:$A$500=A7,IFERROR(INDEX(Milestones!$C$2:$C$25,MATCH(Sprint_Epics!$C$2:$C$500,Milestones!$B$2:$B$25,0)),""),""))} -> PH1, PH1
A8: SP07 | B8: Sprint 7 | C8: Privacy Settings & Preferences | D8: Let a resident control profile visibility, language and notification preferences end to end, per the MVP scope's Settings requirements. | G8: 4 | H8: =COUNTIFS(Stories!$B$2:$B$500,A8,Stories!$L$2:$L$500,"*Done*") -> 0 | I8: =IFERROR(AVERAGEIFS(Stories!$O$2:$O$500,Stories!$B$2:$B$500,A8),0)/100 -> 0 | J8: =IF(COUNTIFS(Stories!$B$2:$B$500,A8,Stories!$L$2:$L$500,"*Blocked*")>0,"🚫 Blocked",IF(I8=1,"✅ Completed",IF(I8>0,"🔄 In Progress","⏳ Planned"))) -> ⏳ Planned | K8: {=_xlfn.TEXTJOIN(", ",TRUE(),IF(Sprint_Epics!$A$2:$A$500=A8,Sprint_Epics!$C$2:$C$500,""))} -> ML4, ML16 | L8: {=_xlfn.TEXTJOIN(", ",TRUE(),IF(Sprint_Epics!$A$2:$A$500=A8,IFERROR(INDEX(Milestones!$C$2:$C$25,MATCH(Sprint_Epics!$C$2:$C$500,Milestones!$B$2:$B$25,0)),""),""))} -> PH1, PH1
A9: SP08 | B9: Sprint 8 | C9: Community Selection & Membership | D9: Let a resident browse approved communities and request to join one end to end. (Community creation itself is admin-managed - see Sprint 9.) | G9: 4 | H9: =COUNTIFS(Stories!$B$2:$B$500,A9,Stories!$L$2:$L$500,"*Done*") -> 0 | I9: =IFERROR(AVERAGEIFS(Stories!$O$2:$O$500,Stories!$B$2:$B$500,A9),0)/100 -> 0 | J9: =IF(COUNTIFS(Stories!$B$2:$B$500,A9,Stories!$L$2:$L$500,"*Blocked*")>0,"🚫 Blocked",IF(I9=1,"✅ Completed",IF(I9>0,"🔄 In Progress","⏳ Planned"))) -> ⏳ Planned | K9: {=_xlfn.TEXTJOIN(", ",TRUE(),IF(Sprint_Epics!$A$2:$A$500=A9,Sprint_Epics!$C$2:$C$500,""))} -> ML5, ML16 | L9: {=_xlfn.TEXTJOIN(", ",TRUE(),IF(Sprint_Epics!$A$2:$A$500=A9,IFERROR(INDEX(Milestones!$C$2:$C$25,MATCH(Sprint_Epics!$C$2:$C$500,Milestones!$B$2:$B$25,0)),""),""))} -> PH1, PH1
A10: SP09 | B10: Sprint 9 | C10: Community Admin & Verification Review | D10: Give an administrator the tools to create communities and approve residency verification and membership requests - the operational counterpart to Sprints 5 and 8. | G10: 4 | H10: =COUNTIFS(Stories!$B$2:$B$500,A10,Stories!$L$2:$L$500,"*Done*") -> 0 | I10: =IFERROR(AVERAGEIFS(Stories!$O$2:$O$500,Stories!$B$2:$B$500,A10),0)/100 -> 0 | J10: =IF(COUNTIFS(Stories!$B$2:$B$500,A10,Stories!$L$2:$L$500,"*Blocked*")>0,"🚫 Blocked",IF(I10=1,"✅ Completed",IF(I10>0,"🔄 In Progress","⏳ Planned"))) -> ⏳ Planned | K10: {=_xlfn.TEXTJOIN(", ",TRUE(),IF(Sprint_Epics!$A$2:$A$500=A10,Sprint_Epics!$C$2:$C$500,""))} -> ML5, ML5, ML13 | L10: {=_xlfn.TEXTJOIN(", ",TRUE(),IF(Sprint_Epics!$A$2:$A$500=A10,IFERROR(INDEX(Milestones!$C$2:$C$25,MATCH(Sprint_Epics!$C$2:$C$500,Milestones!$B$2:$B$25,0)),""),""))} -> PH1, PH1, PH1
A11: SP10 | B11: Sprint 10 | C11: Community Feed - Create & View Posts | D11: Let a resident create a post with text and images and see the community feed end to end, per the MVP scope's Feed requirements. | G11: 5 | H11: =COUNTIFS(Stories!$B$2:$B$500,A11,Stories!$L$2:$L$500,"*Done*") -> 0 | I11: =IFERROR(AVERAGEIFS(Stories!$O$2:$O$500,Stories!$B$2:$B$500,A11),0)/100 -> 0 | J11: =IF(COUNTIFS(Stories!$B$2:$B$500,A11,Stories!$L$2:$L$500,"*Blocked*")>0,"🚫 Blocked",IF(I11=1,"✅ Completed",IF(I11>0,"🔄 In Progress","⏳ Planned"))) -> ⏳ Planned | K11: {=_xlfn.TEXTJOIN(", ",TRUE(),IF(Sprint_Epics!$A$2:$A$500=A11,Sprint_Epics!$C$2:$C$500,""))} -> ML6, ML6, ML18, ML18, ML16 | L11: {=_xlfn.TEXTJOIN(", ",TRUE(),IF(Sprint_Epics!$A$2:$A$500=A11,IFERROR(INDEX(Milestones!$C$2:$C$25,MATCH(Sprint_Epics!$C$2:$C$500,Milestones!$B$2:$B$25,0)),""),""))} -> PH1, PH1, PH1, PH1, PH1
A12: SP11 | B12: Sprint 11 | C12: Post Interactions - Comments, Likes & Quick Reactions | D12: Let a resident comment on, like, and quick-react to a post end to end, per the MVP scope's Post Interactions and Quick Reactions requirements. | G12: 4 | H12: =COUNTIFS(Stories!$B$2:$B$500,A12,Stories!$L$2:$L$500,"*Done*") -> 0 | I12: =IFERROR(AVERAGEIFS(Stories!$O$2:$O$500,Stories!$B$2:$B$500,A12),0)/100 -> 0 | J12: =IF(COUNTIFS(Stories!$B$2:$B$500,A12,Stories!$L$2:$L$500,"*Blocked*")>0,"🚫 Blocked",IF(I12=1,"✅ Completed",IF(I12>0,"🔄 In Progress","⏳ Planned"))) -> ⏳ Planned | K12: {=_xlfn.TEXTJOIN(", ",TRUE(),IF(Sprint_Epics!$A$2:$A$500=A12,Sprint_Epics!$C$2:$C$500,""))} -> ML6, ML6, ML16 | L12: {=_xlfn.TEXTJOIN(", ",TRUE(),IF(Sprint_Epics!$A$2:$A$500=A12,IFERROR(INDEX(Milestones!$C$2:$C$25,MATCH(Sprint_Epics!$C$2:$C$500,Milestones!$B$2:$B$25,0)),""),""))} -> PH1, PH1, PH1
A13: SP12 | B13: Sprint 12 | C13: Save & Report Content | D13: Let a resident bookmark a post and report a post or user end to end, per the MVP scope's Moderation (Report User/Post) requirements. | G13: 4 | H13: =COUNTIFS(Stories!$B$2:$B$500,A13,Stories!$L$2:$L$500,"*Done*") -> 0 | I13: =IFERROR(AVERAGEIFS(Stories!$O$2:$O$500,Stories!$B$2:$B$500,A13),0)/100 -> 0 | J13: =IF(COUNTIFS(Stories!$B$2:$B$500,A13,Stories!$L$2:$L$500,"*Blocked*")>0,"🚫 Blocked",IF(I13=1,"✅ Completed",IF(I13>0,"🔄 In Progress","⏳ Planned"))) -> ⏳ Planned | K13: {=_xlfn.TEXTJOIN(", ",TRUE(),IF(Sprint_Epics!$A$2:$A$500=A13,Sprint_Epics!$C$2:$C$500,""))} -> ML7, ML7, ML16 | L13: {=_xlfn.TEXTJOIN(", ",TRUE(),IF(Sprint_Epics!$A$2:$A$500=A13,IFERROR(INDEX(Milestones!$C$2:$C$25,MATCH(Sprint_Epics!$C$2:$C$500,Milestones!$B$2:$B$25,0)),""),""))} -> PH1, PH1, PH1
A14: SP13 | B14: Sprint 13 | C14: Community Announcements | D14: Let an admin publish a community announcement and a resident see it end to end. Flagging: the MVP scope doc does not explicitly list Announcements as a must-have - confirm before building versus deferring in favor of the existing ALERT post type. | G14: 4 | H14: =COUNTIFS(Stories!$B$2:$B$500,A14,Stories!$L$2:$L$500,"*Done*") -> 0 | I14: =IFERROR(AVERAGEIFS(Stories!$O$2:$O$500,Stories!$B$2:$B$500,A14),0)/100 -> 0 | J14: =IF(COUNTIFS(Stories!$B$2:$B$500,A14,Stories!$L$2:$L$500,"*Blocked*")>0,"🚫 Blocked",IF(I14=1,"✅ Completed",IF(I14>0,"🔄 In Progress","⏳ Planned"))) -> ⏳ Planned | K14: {=_xlfn.TEXTJOIN(", ",TRUE(),IF(Sprint_Epics!$A$2:$A$500=A14,Sprint_Epics!$C$2:$C$500,""))} -> ML7, ML16 | L14: {=_xlfn.TEXTJOIN(", ",TRUE(),IF(Sprint_Epics!$A$2:$A$500=A14,IFERROR(INDEX(Milestones!$C$2:$C$25,MATCH(Sprint_Epics!$C$2:$C$500,Milestones!$B$2:$B$25,0)),""),""))} -> PH1, PH1
... A29: SP28 | B29: Sprint 28 | C29: MVP Release v1.0 | D29: Deploy and finalize the first production-ready release of MyCommunity with all approved MVP functionality. | G29: 2 | H29: =COUNTIFS(Stories!$B$2:$B$500,A29,Stories!$L$2:$L$500,"*Done*") -> 0 | I29: =IFERROR(AVERAGEIFS(Stories!$O$2:$O$500,Stories!$B$2:$B$500,A29),0)/100 -> 0 | J29: =IF(COUNTIFS(Stories!$B$2:$B$500,A29,Stories!$L$2:$L$500,"*Blocked*")>0,"🚫 Blocked",IF(I29=1,"✅ Completed",IF(I29>0,"🔄 In Progress","⏳ Planned"))) -> ⏳ Planned | K29: {=_xlfn.TEXTJOIN(", ",TRUE(),IF(Sprint_Epics!$A$2:$A$500=A29,Sprint_Epics!$C$2:$C$500,""))} -> ML24 | L29: {=_xlfn.TEXTJOIN(", ",TRUE(),IF(Sprint_Epics!$A$2:$A$500=A29,IFERROR(INDEX(Milestones!$C$2:$C$25,MATCH(Sprint_Epics!$C$2:$C$500,Milestones!$B$2:$B$25,0)),""),""))} -> PH1

Sheet Sprint_Epics
A1: Sprint ID | B1: Epic Code | C1: Milestone ID
A2: SP01 | B2: ML1-EP01 | C2: =IFERROR(INDEX(Epics!$B$2:$B$100,MATCH(B2,Epics!$C$2:$C$100,0)),"") -> ML1
A3: SP02 | B3: ML2-EP01 | C3: =IFERROR(INDEX(Epics!$B$2:$B$100,MATCH(B3,Epics!$C$2:$C$100,0)),"") -> ML2
A4: SP02 | B4: ML2-EP02 | C4: =IFERROR(INDEX(Epics!$B$2:$B$100,MATCH(B4,Epics!$C$2:$C$100,0)),"") -> ML2
A5: SP02 | B5: ML14-EP01 | C5: =IFERROR(INDEX(Epics!$B$2:$B$100,MATCH(B5,Epics!$C$2:$C$100,0)),"") -> ML14
A6: SP02 | B6: ML15-EP01 | C6: =IFERROR(INDEX(Epics!$B$2:$B$100,MATCH(B6,Epics!$C$2:$C$100,0)),"") -> ML15
A7: SP03 | B7: ML2-EP03 | C7: =IFERROR(INDEX(Epics!$B$2:$B$100,MATCH(B7,Epics!$C$2:$C$100,0)),"") -> ML2
A8: SP03 | B8: ML2-EP04 | C8: =IFERROR(INDEX(Epics!$B$2:$B$100,MATCH(B8,Epics!$C$2:$C$100,0)),"") -> ML2
A9: SP03 | B9: ML16-EP01 | C9: =IFERROR(INDEX(Epics!$B$2:$B$100,MATCH(B9,Epics!$C$2:$C$100,0)),"") -> ML16
A10: SP04 | B10: ML2-EP05 | C10: =IFERROR(INDEX(Epics!$B$2:$B$100,MATCH(B10,Epics!$C$2:$C$100,0)),"") -> ML2
A11: SP04 | B11: ML3-EP01 | C11: =IFERROR(INDEX(Epics!$B$2:$B$100,MATCH(B11,Epics!$C$2:$C$100,0)),"") -> ML3
A12: SP04 | B12: ML16-EP01 | C12: =IFERROR(INDEX(Epics!$B$2:$B$100,MATCH(B12,Epics!$C$2:$C$100,0)),"") -> ML16
A13: SP05 | B13: ML3-EP03 | C13: =IFERROR(INDEX(Epics!$B$2:$B$100,MATCH(B13,Epics!$C$2:$C$100,0)),"") -> ML3
... A72: SP28 | B72: ML24-EP01 | C72: =IFERROR(INDEX(Epics!$B$2:$B$100,MATCH(B72,Epics!$C$2:$C$100,0)),"") -> ML24

Sheet Stories
A1: Story ID | B1: Sprint ID | C1: Epic Code | D1: Milestone ID | E1: Phase ID | F1: Title | G1: Description | H1: Priority | I1: Estimate (Hours) | J1: Actual Hours | K1: Story Points | L1: Status | M1: Assignee | N1: Depends On | O1: Progress %
A2: BF-001 | B2: SP01 | C2: ML1-EP01 | D2: =IFERROR(INDEX(Epics!$B$2:B$100,MATCH(C2,Epics!$C$2:C$100,0)),"") -> ML1 | E2: =IFERROR(INDEX(Milestones!$C$2:$C$25,MATCH(D2,Milestones!$B$2:$B$25,0)),"") -> PH1 | F2: FastAPI Project Structure | G2: As a developer, I want a standardized FastAPI project structure so that the codebase is modular and scalable. Acceptance Criteria: Project follows the approved folder structure and starts successfully. | H2: High | L2: ✅ Done | O2: =_xlfn.IFS(ISNUMBER(SEARCH("Done",L2)),100,ISNUMBER(SEARCH("In Progress",L2)),50,TRUE(),0) -> 100
A3: BF-002 | B3: SP01 | C3: ML1-EP01 | D3: =IFERROR(INDEX(Epics!$B$2:B$100,MATCH(C3,Epics!$C$2:C$100,0)),"") -> ML1 | E3: =IFERROR(INDEX(Milestones!$C$2:$C$25,MATCH(D3,Milestones!$B$2:$B$25,0)),"") -> PH1 | F3: Centralized Configuration | G3: As a developer, I want all application configuration to be centralized, validated, and loaded from environment variables so that the application is secure, environment independent, and fails fast when required configuration is missing. Acceptance Criteria: Settings are loaded from .env using Pydantic BaseSettings with no hardcoded values. | H3: High | L3: ✅ Done | N3: BF-001 | O3: =_xlfn.IFS(ISNUMBER(SEARCH("Done",L3)),100,ISNUMBER(SEARCH("In Progress",L3)),50,TRUE(),0) -> 100
A4: BF-003 | B4: SP01 | C4: ML1-EP01 | D4: =IFERROR(INDEX(Epics!$B$2:B$100,MATCH(C4,Epics!$C$2:C$100,0)),"") -> ML1 | E4: =IFERROR(INDEX(Milestones!$C$2:$C$25,MATCH(D4,Milestones!$B$2:$B$25,0)),"") -> PH1 | F4: Database Connectivity | G4: As a developer, I want database connectivity configured with SQLAlchemy Async and PostgreSQL so that the application can persist data reliably. Acceptance Criteria: Application successfully connects to PostgreSQL using Async SQLAlchemy. | H4: High | L4: ✅ Done | N4: BF-002 | O4: =_xlfn.IFS(ISNUMBER(SEARCH("Done",L4)),100,ISNUMBER(SEARCH("In Progress",L4)),50,TRUE(),0) -> 100
A5: BF-004 | B5: SP01 | C5: ML1-EP01 | D5: =IFERROR(INDEX(Epics!$B$2:B$100,MATCH(C5,Epics!$C$2:C$100,0)),"") -> ML1 | E5: =IFERROR(INDEX(Milestones!$C$2:$C$25,MATCH(D5,Milestones!$B$2:$B$25,0)),"") -> PH1 | F5: Alembic Migrations | G5: As a developer, I want Alembic configured for database migrations so that schema changes are version controlled. Acceptance Criteria: Initial migration can be created and applied successfully. | H5: High | L5: ✅ Done | N5: BF-003 | O5: =_xlfn.IFS(ISNUMBER(SEARCH("Done",L5)),100,ISNUMBER(SEARCH("In Progress",L5)),50,TRUE(),0) -> 100
A6: BF-005 | B6: SP01 | C6: ML1-EP01 | D6: =IFERROR(INDEX(Epics!$B$2:B$100,MATCH(C6,Epics!$C$2:C$100,0)),"") -> ML1 | E6: =IFERROR(INDEX(Milestones!$C$2:$C$25,MATCH(D6,Milestones!$B$2:$B$25,0)),"") -> PH1 | F6: Application Lifecycle Management | G6: As a developer, I want application lifecycle management configured so that startup and shutdown events are handled correctly. Acceptance Criteria: Lifespan events initialize and release resources without errors. | H6: High | L6: ✅ Done | N6: BF-003 | O6: =_xlfn.IFS(ISNUMBER(SEARCH("Done",L6)),100,ISNUMBER(SEARCH("In Progress",L6)),50,TRUE(),0) -> 100
A7: BF-006 | B7: SP01 | C7: ML1-EP01 | D7: =IFERROR(INDEX(Epics!$B$2:B$100,MATCH(C7,Epics!$C$2:C$100,0)),"") -> ML1 | E7: =IFERROR(INDEX(Milestones!$C$2:$C$25,MATCH(D7,Milestones!$B$2:$B$25,0)),"") -> PH1 | F7: API Versioning | G7: As a developer, I want API versioning established so that future API changes remain backward compatible. Acceptance Criteria: All endpoints are available under /api/v1. | H7: High | L7: ✅ Done | N7: BF-001 | O7: =_xlfn.IFS(ISNUMBER(SEARCH("Done",L7)),100,ISNUMBER(SEARCH("In Progress",L7)),50,TRUE(),0) -> 100
A8: BF-007 | B8: SP01 | C8: ML1-EP01 | D8: =IFERROR(INDEX(Epics!$B$2:B$100,MATCH(C8,Epics!$C$2:C$100,0)),"") -> ML1 | E8: =IFERROR(INDEX(Milestones!$C$2:$C$25,MATCH(D8,Milestones!$B$2:$B$25,0)),"") -> PH1 | F8: Health Check Endpoints | G8: As a developer, I want health check endpoints so that I can verify application and database availability. Acceptance Criteria: Health endpoint returns application status and database connectivity. | H8: High | L8: ✅ Done | N8: BF-003 | O8: =_xlfn.IFS(ISNUMBER(SEARCH("Done",L8)),100,ISNUMBER(SEARCH("In Progress",L8)),50,TRUE(),0) -> 100
A9: BF-008 | B9: SP01 | C9: ML1-EP01 | D9: =IFERROR(INDEX(Epics!$B$2:B$100,MATCH(C9,Epics!$C$2:C$100,0)),"") -> ML1 | E9: =IFERROR(INDEX(Milestones!$C$2:$C$25,MATCH(D9,Milestones!$B$2:$B$25,0)),"") -> PH1 | F9: Structured Logging | G9: As a developer, I want structured logging so that application behavior is easy to monitor and troubleshoot. Acceptance Criteria: Requests, errors, and startup events are logged consistently. | H9: Medium | L9: ✅ Done | N9: BF-002 | O9: =_xlfn.IFS(ISNUMBER(SEARCH("Done",L9)),100,ISNUMBER(SEARCH("In Progress",L9)),50,TRUE(),0) -> 100
A10: BF-009 | B10: SP01 | C10: ML1-EP01 | D10: =IFERROR(INDEX(Epics!$B$2:B$100,MATCH(C10,Epics!$C$2:C$100,0)),"") -> ML1 | E10: =IFERROR(INDEX(Milestones!$C$2:$C$25,MATCH(D10,Milestones!$B$2:$B$25,0)),"") -> PH1 | F10: Global Exception Handling | G10: As a developer, I want global exception handling so that API errors are returned in a consistent format. Acceptance Criteria: Validation, business, and unexpected exceptions return standardized responses. | H10: High | L10: ✅ Done | N10: BF-001 | O10: =_xlfn.IFS(ISNUMBER(SEARCH("Done",L10)),100,ISNUMBER(SEARCH("In Progress",L10)),50,TRUE(),0) -> 100
A11: BF-010 | B11: SP01 | C11: ML1-EP01 | D11: =IFERROR(INDEX(Epics!$B$2:B$100,MATCH(C11,Epics!$C$2:C$100,0)),"") -> ML1 | E11: =IFERROR(INDEX(Milestones!$C$2:$C$25,MATCH(D11,Milestones!$B$2:$B$25,0)),"") -> PH1 | F11: Standardized API Response Models | G11: As a developer, I want reusable standardized API response models so that every API endpoint returns a consistent response contract for success, collections, pagination, and errors. Acceptance Criteria: Reusable generic response models support success, paginated, and standardized error responses compatible with the global exception handler (BF-009); Pydantic v2 generics used where appropriate; Health endpoints updated to the standardized model; OpenAPI reflects the schemas; unit tests validate serialization. | H11: High | L11: ✅ Done | N11: BF-009 | O11: =_xlfn.IFS(ISNUMBER(SEARCH("Done",L11)),100,ISNUMBER(SEARCH("In Progress",L11)),50,TRUE(),0) -> 100
A12: BF-011 | B12: SP01 | C12: ML1-EP01 | D12: =IFERROR(INDEX(Epics!$B$2:B$100,MATCH(C12,Epics!$C$2:C$100,0)),"") -> ML1 | E12: =IFERROR(INDEX(Milestones!$C$2:$C$25,MATCH(D12,Milestones!$B$2:$B$25,0)),"") -> PH1 | F12: Security Utilities | G12: As a developer, I want security utilities prepared so that authentication can be implemented without restructuring the project. Acceptance Criteria: Password hashing, JWT helpers, and security dependencies are available but unused. | H12: Medium | L12: ✅ Done | N12: BF-002 | O12: =_xlfn.IFS(ISNUMBER(SEARCH("Done",L12)),100,ISNUMBER(SEARCH("In Progress",L12)),50,TRUE(),0) -> 100
A13: BF-012 | B13: SP01 | C13: ML1-EP01 | D13: =IFERROR(INDEX(Epics!$B$2:B$100,MATCH(C13,Epics!$C$2:C$100,0)),"") -> ML1 | E13: =IFERROR(INDEX(Milestones!$C$2:$C$25,MATCH(D13,Milestones!$B$2:$B$25,0)),"") -> PH1 | F13: Reusable Repository Layer | G13: As a developer, I want a reusable repository layer that isolates database access from business logic, so that services remain focused on business rules and persistence concerns are centralized, consistent, and easily testable. Acceptance Criteria: Base repository and repository interfaces are implemented. | H13: Medium | L13: ✅ Done | N13: BF-003 | O13: =_xlfn.IFS(ISNUMBER(SEARCH("Done",L13)),100,ISNUMBER(SEARCH("In Progress",L13)),50,TRUE(),0) -> 100
A14: BF-013 | B14: SP01 | C14: ML1-EP01 | D14: =IFERROR(INDEX(Epics!$B$2:B$100,MATCH(C14,Epics!$C$2:C$100,0)),"") -> ML1 | E14: =IFERROR(INDEX(Milestones!$C$2:$C$25,MATCH(D14,Milestones!$B$2:$B$25,0)),"") -> PH1 | F14: Service Layer & Repository Contracts | G14: As a developer, I want a service layer so that business logic is separated from controllers and repositories. Acceptance Criteria: Generic asynchronous BaseRepository implemented with common CRUD operations; repository interfaces defined for future business modules; architecture follows Router -> Service -> Repository -> Database; repositories are the only layer permitted to access the database directly; no business entities or MVP functionality introduced. | H14: Medium | L14: ✅ Done | N14: BF-012 | O14: =_xlfn.IFS(ISNUMBER(SEARCH("Done",L14)),100,ISNUMBER(SEARCH("In Progress",L14)),50,TRUE(),0) -> 100
... A19: BF-018 | B19: SP01 | C19: ML1-EP01 | D19: =IFERROR(INDEX(Epics!$B$2:B$100,MATCH(C19,Epics!$C$2:C$100,0)),"") -> ML1 | E19: =IFERROR(INDEX(Milestones!$C$2:$C$25,MATCH(D19,Milestones!$B$2:$B$25,0)),"") -> PH1 | F19: Backend Onboarding Documentation | G19: As a developer, I want comprehensive project documentation so that any new contributor can quickly understand the backend architecture, set up a local development environment, execute common development tasks, and follow the project's engineering workflow without relying on tribal knowledge. Acceptance Criteria: Root README.md created/updated as the primary onboarding guide covering prerequisites, installation, environment config, structure, dev commands, testing, linting, migrations, API docs, and workflow; all commands verified against the current repository. | H19: Low | L19: ✅ Done | N19: BF-001, BF-002, BF-003, BF-004, BF-005, BF-006, BF-007, BF-008, BF-009, BF-010, BF-011, BF-012, BF-013, BF-014, BF-015, BF-016, BF-017 | O19: =_xlfn.IFS(ISNUMBER(SEARCH("Done",L19)),100,ISNUMBER(SEARCH("In Progress",L19)),50,TRUE(),0) -> 100
A20: UR-001 | B20: SP02 | C20: ML2-EP01 | D20: =IFERROR(INDEX(Epics!$B$2:$B$100,MATCH(C20,Epics!$C$2:$C$100,0)),"") -> ML2 | E20: =IFERROR(INDEX(Milestones!$C$2:$C$25,MATCH(D20,Milestones!$B$2:$B$25,0)),"") -> PH2 | F20: Resident User Data Model, Migration & Repository | G20: As a developer, I want to implement the foundational Resident User persistence layer by introducing the SQLAlchemy User entity, Alembic migration, and repository so that resident identity data conforms to the approved Firebase-first authentication architecture. The User entity will represent only identity and account metadata, while authentication credentials remain exclusively managed by Firebase. This aligns with the approved Identity & Access and Resident domains, where a User is the aggregate root for future Profile, Device, Session, and Verification entities. Acceptance Criteria: Implement a production-ready SQLAlchemy User model using UUID primary keys and the project's shared base entity. The model includes, at minimum: id firebase_uid mobile_number email (nullable) first_name last_name profile_photo_url account_status Standard audit fields inherited from the base model. firebase_uid is mandatory and uniquely constrained. mobile_number is mandatory and uniquely constrained. email is optional but uniquely constrained when present. account_status defaults to PENDING_VERIFICATION. No password, password_hash, password_salt, login_secret, or equivalent credential storage is introduced because authentication is delegated entirely to Firebase. Generate an Alembic migration that creates the users table, indexes, and all required constraints. Implement the User repository following the existing repository abstraction and project repository pattern. Repository exposes only foundational persistence operations required for future authentication stories: create get_by_id get_by_firebase_uid get_by_mobile_number get_by_email exists_by_mobile_number exists_by_email Repository contains no business logic. Migration applies and rolls back successfully. All existing tests continue to pass, and new repository tests are added where appropriate. | H20: High | L20: ⏳ Planned | N20: BF-003, BF-012 | O20: =_xlfn.IFS(ISNUMBER(SEARCH("Done",L20)),100,ISNUMBER(SEARCH("In Progress",L20)),50,TRUE(),0) -> 0
A21: UR-002 | B21: SP02 | C21: ML2-EP02 | D21: =IFERROR(INDEX(Epics!$B$2:$B$100,MATCH(C21,Epics!$C$2:$C$100,0)),"") -> ML2 | E21: =IFERROR(INDEX(Milestones!$C$2:$C$25,MATCH(D21,Milestones!$B$2:$B$25,0)),"") -> PH2 | F21: Firebase Token Verification, Registration & Login API | G21: As a resident, I want to register and log in using my Firebase-verified mobile number so the backend can create or resolve my profile and issue an authorization JWT. Acceptance Criteria: Firebase Admin SDK verifies ID tokens; /auth/register creates the User (PENDING_VERIFICATION) and Device record; /auth/login resolves the user, creates a Session, and returns a backend JWT; duplicate accounts are rejected with a 409. | H21: High | L21: ⏳ Planned | N21: UR-001 | O21: =_xlfn.IFS(ISNUMBER(SEARCH("Done",L21)),100,ISNUMBER(SEARCH("In Progress",L21)),50,TRUE(),0) -> 0
A22: UR-003 | B22: SP02 | C22: ML2-EP02 | D22: =IFERROR(INDEX(Epics!$B$2:$B$100,MATCH(C22,Epics!$C$2:$C$100,0)),"") -> ML2 | E22: =IFERROR(INDEX(Milestones!$C$2:$C$25,MATCH(D22,Milestones!$B$2:$B$25,0)),"") -> PH2 | F22: Session, Security & Audit Guardrails | G22: As a platform owner, I want registration/login rate-limited, account status enforced, and every attempt audit-logged so the flow is safe to expose publicly. Acceptance Criteria: IP/device rate limiting on register and login; login blocked for suspended/inactive/pending accounts with a distinct standardized error; Audit Log entries written for both flows. | H22: Medium | L22: ⏳ Planned | N22: UR-002 | O22: =_xlfn.IFS(ISNUMBER(SEARCH("Done",L22)),100,ISNUMBER(SEARCH("In Progress",L22)),50,TRUE(),0) -> 0
A23: FB-001 | B23: SP02 | C23: ML14-EP01 | D23: =IFERROR(INDEX(Epics!$B$2:$B$100,MATCH(C23,Epics!$C$2:$C$100,0)),"") -> ML14 | E23: =IFERROR(INDEX(Milestones!$C$2:$C$25,MATCH(D23,Milestones!$B$2:$B$25,0)),"") -> PH2 | F23: Flutter Project Bootstrap for Auth Track | G23: As a developer, I want a minimal Flutter scaffold (routing, theming, Firebase init) so auth screens can be built now, ahead of the full app architecture milestone. Acceptance Criteria: Flutter project runs on iOS/Android with a basic navigation shell and Firebase SDK initialized; full design system remains deferred. | H23: High | L23: ⏳ Planned | O23: =_xlfn.IFS(ISNUMBER(SEARCH("Done",L23)),100,ISNUMBER(SEARCH("In Progress",L23)),50,TRUE(),0) -> 0
A24: FA-001 | B24: SP02 | C24: ML15-EP01 | D24: =IFERROR(INDEX(Epics!$B$2:$B$100,MATCH(C24,Epics!$C$2:$C$100,0)),"") -> ML15 | E24: =IFERROR(INDEX(Milestones!$C$2:$C$25,MATCH(D24,Milestones!$B$2:$B$25,0)),"") -> PH2 | F24: Mobile Number Entry & OTP Verification Screens | G24: As a resident, I want to enter my mobile number and the OTP sent to it so I can begin registration or login. Acceptance Criteria: Country-code picker (default +971), number validation, Firebase phone-auth OTP request; OTP screen has a resend timer and clear invalid/expired-code states. | H24: High | L24: ⏳ Planned | N24: FB-001 | O24: =_xlfn.IFS(ISNUMBER(SEARCH("Done",L24)),100,ISNUMBER(SEARCH("In Progress",L24)),50,TRUE(),0) -> 0
A25: FA-002 | B25: SP02 | C25: ML15-EP01 | D25: =IFERROR(INDEX(Epics!$B$2:$B$100,MATCH(C25,Epics!$C$2:$C$100,0)),"") -> ML15 | E25: =IFERROR(INDEX(Milestones!$C$2:$C$25,MATCH(D25,Milestones!$B$2:$B$25,0)),"") -> PH2 | F25: Registration Profile Capture & Auto-Login | G25: As a new resident, I want to enter my basic profile after OTP verification so my account is created, and as a returning resident I want the app to log me in automatically when I already have a valid session. Acceptance Criteria: New numbers route to a profile-capture screen that calls UR-002's register endpoint; existing numbers and valid sessions route straight to home via the login endpoint. | H25: High | L25: ⏳ Planned | N25: FA-001, UR-002 | O25: =_xlfn.IFS(ISNUMBER(SEARCH("Done",L25)),100,ISNUMBER(SEARCH("In Progress",L25)),50,TRUE(),0) -> 0
A26: FA-003 | B26: SP02 | C26: ML15-EP01 | D26: =IFERROR(INDEX(Epics!$B$2:$B$100,MATCH(C26,Epics!$C$2:$C$100,0)),"") -> ML15 | E26: =IFERROR(INDEX(Milestones!$C$2:$C$25,MATCH(D26,Milestones!$B$2:$B$25,0)),"") -> PH2 | F26: Authentication End-to-End Testing | G26: As a developer, I want backend and Flutter tests for the full registration/login flow so regressions are caught before release. Acceptance Criteria: Backend tests mock Firebase Admin verification and cover duplicate/invalid-token/blocked-account cases; a Flutter integration test exercises mobile-entry through OTP to home against a Firebase test project. | H26: Medium | L26: ⏳ Planned | N26: UR-003, FA-002 | O26: =_xlfn.IFS(ISNUMBER(SEARCH("Done",L26)),100,ISNUMBER(SEARCH("In Progress",L26)),50,TRUE(),0) -> 0
A27: AS-001 | B27: SP03 | C27: ML2-EP03 | D27: =IFERROR(INDEX(Epics!$B$2:$B$100,MATCH(C27,Epics!$C$2:$C$100,0)),"") -> ML2 | E27: =IFERROR(INDEX(Milestones!$C$2:$C$25,MATCH(D27,Milestones!$B$2:$B$25,0)),"") -> PH2 | F27: Refresh Token Data Model & Rotation API | G27: As a developer, I want refresh tokens modeled and rotated per the Authentication Module schema so access tokens can be renewed securely without re-verifying via Firebase every time. Acceptance Criteria: Refresh Token table implemented (hashed storage only); /auth/refresh issues a new JWT and rotates the token; revoked/expired tokens are rejected. | H27: High | L27: ⏳ Planned | N27: UR-002 | O27: =_xlfn.IFS(ISNUMBER(SEARCH("Done",L27)),100,ISNUMBER(SEARCH("In Progress",L27)),50,TRUE(),0) -> 0
A28: AS-002 | B28: SP03 | C28: ML2-EP04 | D28: =IFERROR(INDEX(Epics!$B$2:$B$100,MATCH(C28,Epics!$C$2:$C$100,0)),"") -> ML2 | E28: =IFERROR(INDEX(Milestones!$C$2:$C$25,MATCH(D28,Milestones!$B$2:$B$25,0)),"") -> PH2 | F28: Role-Based Authorization Middleware | G28: As a developer, I want resident/community-admin/platform-admin roles enforced on protected endpoints so authorization isn't left to ad-hoc checks in each route. Acceptance Criteria: Role field added to User/session context; a reusable dependency enforces required roles per endpoint and returns a standardized 403 on mismatch. | H28: High | L28: ⏳ Planned | N28: UA-004 | O28: =_xlfn.IFS(ISNUMBER(SEARCH("Done",L28)),100,ISNUMBER(SEARCH("In Progress",L28)),50,TRUE(),0) -> 0
A29: AS-003 | B29: SP03 | C29: ML16-EP01 | D29: =IFERROR(INDEX(Epics!$B$2:$B$100,MATCH(C29,Epics!$C$2:$C$100,0)),"") -> ML16 | E29: =IFERROR(INDEX(Milestones!$C$2:$C$25,MATCH(D29,Milestones!$B$2:$B$25,0)),"") -> PH2 | F29: Active Sessions Screen | G29: As a resident, I want to see my active devices/sessions and log out of any of them so I can control access to my account. Acceptance Criteria: Flutter screen lists sessions from UA-003's Session table via a new list endpoint, with a per-session logout action that revokes that session's tokens. | H29: Medium | L29: ⏳ Planned | N29: AS-001 | O29: =_xlfn.IFS(ISNUMBER(SEARCH("Done",L29)),100,ISNUMBER(SEARCH("In Progress",L29)),50,TRUE(),0) -> 0
A30: AS-004 | B30: SP03 | C30: ML2-EP03 | D30: =IFERROR(INDEX(Epics!$B$2:$B$100,MATCH(C30,Epics!$C$2:$C$100,0)),"") -> ML2 | E30: =IFERROR(INDEX(Milestones!$C$2:$C$25,MATCH(D30,Milestones!$B$2:$B$25,0)),"") -> PH2 | F30: Session & Authorization Testing | G30: As a developer, I want tests for token refresh, revocation and role enforcement so this security-sensitive area doesn't regress silently. Acceptance Criteria: Tests cover refresh rotation, revoked-token rejection, and role-mismatch 403s; all pass in CI. | H30: Medium | L30: ⏳ Planned | N30: AS-001, AS-002, AS-003 | O30: =_xlfn.IFS(ISNUMBER(SEARCH("Done",L30)),100,ISNUMBER(SEARCH("In Progress",L30)),50,TRUE(),0) -> 0
A31: AV-001 | B31: SP04 | C31: ML3-EP01 | D31: =IFERROR(INDEX(Epics!$B$2:$B$100,MATCH(C31,Epics!$C$2:$C$100,0)),"") -> ML3 | E31: =IFERROR(INDEX(Milestones!$C$2:$C$25,MATCH(D31,Milestones!$B$2:$B$25,0)),"") -> PH2 | F31: Email Verification Data Model & Send API | G31: As a resident, I want to add an email address and receive a verification link/code so it can be used for account recovery and important communication. Acceptance Criteria: Email + verification-token fields used on the User table; an endpoint sends a verification email via the configured provider. | H31: High | L31: ⏳ Planned | N31: UR-001 | O31: =_xlfn.IFS(ISNUMBER(SEARCH("Done",L31)),100,ISNUMBER(SEARCH("In Progress",L31)),50,TRUE(),0) -> 0
A32: AV-002 | B32: SP04 | C32: ML2-EP05 | D32: =IFERROR(INDEX(Epics!$B$2:$B$100,MATCH(C32,Epics!$C$2:$C$100,0)),"") -> ML2 | E32: =IFERROR(INDEX(Milestones!$C$2:$C$25,MATCH(D32,Milestones!$B$2:$B$25,0)),"") -> PH2 | F32: Verify Email & Account Recovery API | G32: As a resident, I want to confirm my email and use it to regain access if I lose my mobile number so I'm not permanently locked out. Acceptance Criteria: Verify-email endpoint sets is_email_verified=true; a documented, support-assisted recovery path exists for lost-phone cases (self-service phone-number change is flagged as a follow-up decision, not built here). | H32: High | L32: ⏳ Planned | N32: AV-001 | O32: =_xlfn.IFS(ISNUMBER(SEARCH("Done",L32)),100,ISNUMBER(SEARCH("In Progress",L32)),50,TRUE(),0) -> 0
A33: AV-003 | B33: SP04 | C33: ML16-EP01 | D33: =IFERROR(INDEX(Epics!$B$2:$B$100,MATCH(C33,Epics!$C$2:$C$100,0)),"") -> ML16 | E33: =IFERROR(INDEX(Milestones!$C$2:$C$25,MATCH(D33,Milestones!$B$2:$B$25,0)),"") -> PH2 | F33: Add & Verify Email Screen | G33: As a resident, I want a settings screen to add my email and confirm the verification code so I can complete this from the app. Acceptance Criteria: Flutter screen submits the email, shows a pending-verification state, and confirms once AV-002's verify endpoint succeeds. | H33: Medium | L33: ⏳ Planned | N33: AV-002 | O33: =_xlfn.IFS(ISNUMBER(SEARCH("Done",L33)),100,ISNUMBER(SEARCH("In Progress",L33)),50,TRUE(),0) -> 0
A34: AV-004 | B34: SP04 | C34: ML3-EP01 | D34: =IFERROR(INDEX(Epics!$B$2:$B$100,MATCH(C34,Epics!$C$2:$C$100,0)),"") -> ML3 | E34: =IFERROR(INDEX(Milestones!$C$2:$C$25,MATCH(D34,Milestones!$B$2:$B$25,0)),"") -> PH2 | F34: Email Verification Testing | G34: As a developer, I want tests for the email verification and recovery flow so regressions are caught early. Acceptance Criteria: Tests cover send, verify, expired-code and duplicate-email cases. | H34: Medium | L34: ⏳ Planned | N34: AV-002, AV-003 | O34: =_xlfn.IFS(ISNUMBER(SEARCH("Done",L34)),100,ISNUMBER(SEARCH("In Progress",L34)),50,TRUE(),0) -> 0
A35: RV-001 | B35: SP05 | C35: ML3-EP03 | D35: =IFERROR(INDEX(Epics!$B$2:$B$100,MATCH(C35,Epics!$C$2:$C$100,0)),"") -> ML3 | E35: =IFERROR(INDEX(Milestones!$C$2:$C$25,MATCH(D35,Milestones!$B$2:$B$25,0)),"") -> PH2 | F35: Verification & Verification Document Data Model | G35: As a developer, I want Verification and Verification Document tables (per the Foundation Module schema) so Ejari/DEWA submissions and their review status are tracked per resident. Acceptance Criteria: Tables implemented with status (PENDING/APPROVED/REJECTED) and a link to uploaded document files. | H35: High | L35: ⏳ Planned | N35: BF-012 | O35: =_xlfn.IFS(ISNUMBER(SEARCH("Done",L35)),100,ISNUMBER(SEARCH("In Progress",L35)),50,TRUE(),0) -> 0
... A112: AP-005 | B112: SP23 | C112: ML13-EP01 | D112: =IFERROR(INDEX(Epics!$B$2:$B$100,MATCH(C112,Epics!$C$2:$C$100,0)),"") -> ML13 | E112: =IFERROR(INDEX(Milestones!$C$2:$C$25,MATCH(D112,Milestones!$B$2:$B$25,0)),"") -> PH2 | F112: Admin Portal Testing | G112: As a developer, I want tests for the admin dashboard, config and user administration so this operational surface is reliable. Acceptance Criteria: Tests cover dashboard counts, config updates, and suspend/reinstate transitions. | H112: Medium | L112: ⏳ Planned | N112: AP-001, AP-002, AP-003 | O112: =_xlfn.IFS(ISNUMBER(SEARCH("Done",L112)),100,ISNUMBER(SEARCH("In Progress",L112)),50,TRUE(),0) -> 0
A113: PF-001 | B113: SP24 | C113: ML20-EP01 | D113: =IFERROR(INDEX(Epics!$B$2:$B$100,MATCH(C113,Epics!$C$2:$C$100,0)),"") -> ML20 | E113: =IFERROR(INDEX(Milestones!$C$2:$C$25,MATCH(D113,Milestones!$B$2:$B$25,0)),"") -> PH3 | F113: Database & API Performance Review | G113: As a developer, I want slow queries and endpoints identified and optimized so the platform performs well under real usage. Acceptance Criteria: Query plans reviewed for the highest-traffic endpoints (feed, search, notifications); indexes added where missing. | H113: High | L113: ⏳ Planned | O113: =_xlfn.IFS(ISNUMBER(SEARCH("Done",L113)),100,ISNUMBER(SEARCH("In Progress",L113)),50,TRUE(),0) -> 0
A114: PF-002 | B114: SP24 | C114: ML20-EP02 | D114: =IFERROR(INDEX(Epics!$B$2:$B$100,MATCH(C114,Epics!$C$2:$C$100,0)),"") -> ML20 | E114: =IFERROR(INDEX(Milestones!$C$2:$C$25,MATCH(D114,Milestones!$B$2:$B$25,0)),"") -> PH3 | F114: Caching & Scalability Improvements | G114: As a developer, I want caching applied to expensive, frequently-read data (feed, community list) so response times remain low as usage grows. Acceptance Criteria: A caching layer is added with sensible invalidation for feed and community-list reads. | H114: Medium | L114: ⏳ Planned | N114: PF-001 | O114: =_xlfn.IFS(ISNUMBER(SEARCH("Done",L114)),100,ISNUMBER(SEARCH("In Progress",L114)),50,TRUE(),0) -> 0
A115: PF-003 | B115: SP24 | C115: ML20-EP02 | D115: =IFERROR(INDEX(Epics!$B$2:$B$100,MATCH(C115,Epics!$C$2:$C$100,0)),"") -> ML20 | E115: =IFERROR(INDEX(Milestones!$C$2:$C$25,MATCH(D115,Milestones!$B$2:$B$25,0)),"") -> PH3 | F115: Mobile Performance Profiling | G115: As a developer, I want the Flutter app profiled for jank and slow screens so the mobile experience feels responsive. Acceptance Criteria: Key screens (feed, search) profiled and optimized against a target frame budget. | H115: Medium | L115: ⏳ Planned | O115: =_xlfn.IFS(ISNUMBER(SEARCH("Done",L115)),100,ISNUMBER(SEARCH("In Progress",L115)),50,TRUE(),0) -> 0
A116: PF-004 | B116: SP24 | C116: ML20-EP01 | D116: =IFERROR(INDEX(Epics!$B$2:$B$100,MATCH(C116,Epics!$C$2:$C$100,0)),"") -> ML20 | E116: =IFERROR(INDEX(Milestones!$C$2:$C$25,MATCH(D116,Milestones!$B$2:$B$25,0)),"") -> PH3 | F116: Load Testing & Benchmarks | G116: As a developer, I want load tests against key endpoints so performance regressions are caught before release. Acceptance Criteria: Baseline benchmarks recorded for feed, search and notification delivery under simulated concurrent load. | H116: Medium | L116: ⏳ Planned | N116: PF-001, PF-002 | O116: =_xlfn.IFS(ISNUMBER(SEARCH("Done",L116)),100,ISNUMBER(SEARCH("In Progress",L116)),50,TRUE(),0) -> 0
A117: SH-001 | B117: SP25 | C117: ML21-EP01 | D117: =IFERROR(INDEX(Epics!$B$2:$B$100,MATCH(C117,Epics!$C$2:$C$100,0)),"") -> ML21 | E117: =IFERROR(INDEX(Milestones!$C$2:$C$25,MATCH(D117,Milestones!$B$2:$B$25,0)),"") -> PH3 | F117: Security Testing & Vulnerability Remediation | G117: As a platform owner, I want a security pass across the API so known vulnerability classes (injection, broken access control, etc.) are checked and fixed. Acceptance Criteria: OWASP-aligned review completed; findings triaged and remediated or explicitly accepted. | H117: High | L117: ⏳ Planned | O117: =_xlfn.IFS(ISNUMBER(SEARCH("Done",L117)),100,ISNUMBER(SEARCH("In Progress",L117)),50,TRUE(),0) -> 0
A118: SH-002 | B118: SP25 | C118: ML21-EP02 | D118: =IFERROR(INDEX(Epics!$B$2:$B$100,MATCH(C118,Epics!$C$2:$C$100,0)),"") -> ML21 | E118: =IFERROR(INDEX(Milestones!$C$2:$C$25,MATCH(D118,Milestones!$B$2:$B$25,0)),"") -> PH3 | F118: Platform-Wide Rate Limiting & Abuse Hardening | G118: As a platform owner, I want rate limiting extended from auth/registration to all public endpoints so abuse is mitigated everywhere, not just at login. Acceptance Criteria: Rate limits configured per endpoint category via centralized settings. | H118: High | L118: ⏳ Planned | N118: SH-001 | O118: =_xlfn.IFS(ISNUMBER(SEARCH("Done",L118)),100,ISNUMBER(SEARCH("In Progress",L118)),50,TRUE(),0) -> 0
